[25/Dec/2017 07:28:39] ERROR [django.request:256] Internal Server Error: /explore/get_results_by_instance_keyword
Traceback (most recent call last):
  File "/home/mdcs/anaconda2/lib/python2.7/site-packages/django/core/handlers/base.py", line 132, in get_response
    response = wrapped_callback(request, *callback_args, **callback_kwargs)
  File "/home/mdcs/Documents/MDCS-stable/explore/ajax.py", line 464, in get_results_by_instance_keyword
    template = loader.get_template('explore/explore_result_keyword.html')
  File "/home/mdcs/Documents/MDCS-stable/explore/ajax.py", line 527, in get_result_list
    
  File "/home/mdcs/anaconda2/lib/python2.7/site-packages/django/db/models/manager.py", line 127, in manager_method
    return getattr(self.get_queryset(), name)(*args, **kwargs)
  File "/home/mdcs/anaconda2/lib/python2.7/site-packages/django/db/models/query.py", line 334, in get
    self.model._meta.object_name
DoesNotExist: dataProfile matching query does not exist.
[25/Dec/2017 20:53:49] ERROR [django.request:256] Internal Server Error: /explore/get_results_by_instance_keyword
Traceback (most recent call last):
  File "/home/mdcs/anaconda2/lib/python2.7/site-packages/django/core/handlers/base.py", line 132, in get_response
    response = wrapped_callback(request, *callback_args, **callback_kwargs)
  File "/home/mdcs/Documents/MDCS-stable/explore/ajax.py", line 464, in get_results_by_instance_keyword
    template = loader.get_template('explore/explore_result_keyword.html')
  File "/home/mdcs/Documents/MDCS-stable/explore/ajax.py", line 527, in get_result_list
    
  File "/home/mdcs/anaconda2/lib/python2.7/site-packages/django/db/models/manager.py", line 127, in manager_method
    return getattr(self.get_queryset(), name)(*args, **kwargs)
  File "/home/mdcs/anaconda2/lib/python2.7/site-packages/django/db/models/query.py", line 334, in get
    self.model._meta.object_name
DoesNotExist: dataProfile matching query does not exist.
[25/Dec/2017 20:53:51] ERROR [django.request:256] Internal Server Error: /explore/get_results_by_instance_keyword
Traceback (most recent call last):
  File "/home/mdcs/anaconda2/lib/python2.7/site-packages/django/core/handlers/base.py", line 132, in get_response
    response = wrapped_callback(request, *callback_args, **callback_kwargs)
  File "/home/mdcs/Documents/MDCS-stable/explore/ajax.py", line 464, in get_results_by_instance_keyword
    template = loader.get_template('explore/explore_result_keyword.html')
  File "/home/mdcs/Documents/MDCS-stable/explore/ajax.py", line 527, in get_result_list
    
  File "/home/mdcs/anaconda2/lib/python2.7/site-packages/django/db/models/manager.py", line 127, in manager_method
    return getattr(self.get_queryset(), name)(*args, **kwargs)
  File "/home/mdcs/anaconda2/lib/python2.7/site-packages/django/db/models/query.py", line 334, in get
    self.model._meta.object_name
DoesNotExist: dataProfile matching query does not exist.
[25/Dec/2017 21:09:11] ERROR [django.request:256] Internal Server Error: /explore/get_results_by_instance_keyword
Traceback (most recent call last):
  File "/home/mdcs/anaconda2/lib/python2.7/site-packages/django/core/handlers/base.py", line 132, in get_response
    response = wrapped_callback(request, *callback_args, **callback_kwargs)
  File "/home/mdcs/Documents/MDCS-stable/explore/ajax.py", line 465, in get_results_by_instance_keyword
    temp1=get_result_list(instanceResults,request)
  File "/home/mdcs/Documents/MDCS-stable/explore/ajax.py", line 528, in get_result_list
    data = dataProfile.objects.get(xmlData=temp_result["_id"])
  File "/home/mdcs/anaconda2/lib/python2.7/site-packages/django/db/models/manager.py", line 127, in manager_method
    return getattr(self.get_queryset(), name)(*args, **kwargs)
  File "/home/mdcs/anaconda2/lib/python2.7/site-packages/django/db/models/query.py", line 334, in get
    self.model._meta.object_name
DoesNotExist: dataProfile matching query does not exist.
[25/Dec/2017 21:09:54] ERROR [django.request:256] Internal Server Error: /explore/get_results_by_instance_keyword
Traceback (most recent call last):
  File "/home/mdcs/anaconda2/lib/python2.7/site-packages/django/core/handlers/base.py", line 132, in get_response
    response = wrapped_callback(request, *callback_args, **callback_kwargs)
  File "/home/mdcs/Documents/MDCS-stable/explore/ajax.py", line 465, in get_results_by_instance_keyword
    temp1=get_result_list(instanceResults,request)
  File "/home/mdcs/Documents/MDCS-stable/explore/ajax.py", line 528, in get_result_list
    data = dataProfile.objects.get(xmlData=temp_result["_id"])
  File "/home/mdcs/anaconda2/lib/python2.7/site-packages/django/db/models/manager.py", line 127, in manager_method
    return getattr(self.get_queryset(), name)(*args, **kwargs)
  File "/home/mdcs/anaconda2/lib/python2.7/site-packages/django/db/models/query.py", line 334, in get
    self.model._meta.object_name
DoesNotExist: dataProfile matching query does not exist.
[25/Dec/2017 21:09:57] ERROR [django.request:256] Internal Server Error: /explore/get_results_by_instance_keyword
Traceback (most recent call last):
  File "/home/mdcs/anaconda2/lib/python2.7/site-packages/django/core/handlers/base.py", line 132, in get_response
    response = wrapped_callback(request, *callback_args, **callback_kwargs)
  File "/home/mdcs/Documents/MDCS-stable/explore/ajax.py", line 465, in get_results_by_instance_keyword
    temp1=get_result_list(instanceResults,request)
  File "/home/mdcs/Documents/MDCS-stable/explore/ajax.py", line 528, in get_result_list
    data = dataProfile.objects.get(xmlData=temp_result["_id"])
  File "/home/mdcs/anaconda2/lib/python2.7/site-packages/django/db/models/manager.py", line 127, in manager_method
    return getattr(self.get_queryset(), name)(*args, **kwargs)
  File "/home/mdcs/anaconda2/lib/python2.7/site-packages/django/db/models/query.py", line 334, in get
    self.model._meta.object_name
DoesNotExist: dataProfile matching query does not exist.
[25/Dec/2017 21:13:04] ERROR [django.request:256] Internal Server Error: /explore/get_results_by_instance_keyword
Traceback (most recent call last):
  File "/home/mdcs/anaconda2/lib/python2.7/site-packages/django/core/handlers/base.py", line 132, in get_response
    response = wrapped_callback(request, *callback_args, **callback_kwargs)
  File "/home/mdcs/Documents/MDCS-stable/explore/ajax.py", line 468, in get_results_by_instance_keyword
    temp1=get_result_list(instanceResults,request)
  File "/home/mdcs/Documents/MDCS-stable/explore/ajax.py", line 531, in get_result_list
    data = dataProfile.objects.get(xmlData=temp_result["_id"])
  File "/home/mdcs/anaconda2/lib/python2.7/site-packages/django/db/models/manager.py", line 127, in manager_method
    return getattr(self.get_queryset(), name)(*args, **kwargs)
  File "/home/mdcs/anaconda2/lib/python2.7/site-packages/django/db/models/query.py", line 334, in get
    self.model._meta.object_name
DoesNotExist: dataProfile matching query does not exist.
[25/Dec/2017 21:13:06] ERROR [django.request:256] Internal Server Error: /explore/get_results_by_instance_keyword
Traceback (most recent call last):
  File "/home/mdcs/anaconda2/lib/python2.7/site-packages/django/core/handlers/base.py", line 132, in get_response
    response = wrapped_callback(request, *callback_args, **callback_kwargs)
  File "/home/mdcs/Documents/MDCS-stable/explore/ajax.py", line 468, in get_results_by_instance_keyword
    temp1=get_result_list(instanceResults,request)
  File "/home/mdcs/Documents/MDCS-stable/explore/ajax.py", line 531, in get_result_list
    data = dataProfile.objects.get(xmlData=temp_result["_id"])
  File "/home/mdcs/anaconda2/lib/python2.7/site-packages/django/db/models/manager.py", line 127, in manager_method
    return getattr(self.get_queryset(), name)(*args, **kwargs)
  File "/home/mdcs/anaconda2/lib/python2.7/site-packages/django/db/models/query.py", line 334, in get
    self.model._meta.object_name
DoesNotExist: dataProfile matching query does not exist.
[25/Dec/2017 21:16:52] ERROR [django.request:256] Internal Server Error: /explore/get_results_by_instance_keyword
Traceback (most recent call last):
  File "/home/mdcs/anaconda2/lib/python2.7/site-packages/django/core/handlers/base.py", line 132, in get_response
    response = wrapped_callback(request, *callback_args, **callback_kwargs)
  File "/home/mdcs/Documents/MDCS-stable/explore/ajax.py", line 467, in get_results_by_instance_keyword
    temp1=get_result_list(instanceResults,request)
  File "/home/mdcs/Documents/MDCS-stable/explore/ajax.py", line 531, in get_result_list
    data = dataProfile.objects.get(xmlData=temp_result["_id"])
  File "/home/mdcs/anaconda2/lib/python2.7/site-packages/django/db/models/manager.py", line 127, in manager_method
    return getattr(self.get_queryset(), name)(*args, **kwargs)
  File "/home/mdcs/anaconda2/lib/python2.7/site-packages/django/db/models/query.py", line 334, in get
    self.model._meta.object_name
DoesNotExist: dataProfile matching query does not exist.
[25/Dec/2017 21:16:54] ERROR [django.request:256] Internal Server Error: /explore/get_results_by_instance_keyword
Traceback (most recent call last):
  File "/home/mdcs/anaconda2/lib/python2.7/site-packages/django/core/handlers/base.py", line 132, in get_response
    response = wrapped_callback(request, *callback_args, **callback_kwargs)
  File "/home/mdcs/Documents/MDCS-stable/explore/ajax.py", line 467, in get_results_by_instance_keyword
    temp1=get_result_list(instanceResults,request)
  File "/home/mdcs/Documents/MDCS-stable/explore/ajax.py", line 531, in get_result_list
    data = dataProfile.objects.get(xmlData=temp_result["_id"])
  File "/home/mdcs/anaconda2/lib/python2.7/site-packages/django/db/models/manager.py", line 127, in manager_method
    return getattr(self.get_queryset(), name)(*args, **kwargs)
  File "/home/mdcs/anaconda2/lib/python2.7/site-packages/django/db/models/query.py", line 334, in get
    self.model._meta.object_name
DoesNotExist: dataProfile matching query does not exist.
[25/Dec/2017 21:24:05] ERROR [django.request:256] Internal Server Error: /explore/get_results_by_instance_keyword
Traceback (most recent call last):
  File "/home/mdcs/anaconda2/lib/python2.7/site-packages/django/core/handlers/base.py", line 132, in get_response
    response = wrapped_callback(request, *callback_args, **callback_kwargs)
  File "/home/mdcs/Documents/MDCS-stable/explore/ajax.py", line 468, in get_results_by_instance_keyword
    temp1=get_result_list(instanceResults,request)
  File "/home/mdcs/Documents/MDCS-stable/explore/ajax.py", line 532, in get_result_list
    data = dataProfile.objects.get(xmlData=temp_result["_id"])
  File "/home/mdcs/anaconda2/lib/python2.7/site-packages/django/db/models/manager.py", line 127, in manager_method
    return getattr(self.get_queryset(), name)(*args, **kwargs)
  File "/home/mdcs/anaconda2/lib/python2.7/site-packages/django/db/models/query.py", line 334, in get
    self.model._meta.object_name
DoesNotExist: dataProfile matching query does not exist.
[25/Dec/2017 21:24:07] ERROR [django.request:256] Internal Server Error: /explore/get_results_by_instance_keyword
Traceback (most recent call last):
  File "/home/mdcs/anaconda2/lib/python2.7/site-packages/django/core/handlers/base.py", line 132, in get_response
    response = wrapped_callback(request, *callback_args, **callback_kwargs)
  File "/home/mdcs/Documents/MDCS-stable/explore/ajax.py", line 468, in get_results_by_instance_keyword
    temp1=get_result_list(instanceResults,request)
  File "/home/mdcs/Documents/MDCS-stable/explore/ajax.py", line 532, in get_result_list
    data = dataProfile.objects.get(xmlData=temp_result["_id"])
  File "/home/mdcs/anaconda2/lib/python2.7/site-packages/django/db/models/manager.py", line 127, in manager_method
    return getattr(self.get_queryset(), name)(*args, **kwargs)
  File "/home/mdcs/anaconda2/lib/python2.7/site-packages/django/db/models/query.py", line 334, in get
    self.model._meta.object_name
DoesNotExist: dataProfile matching query does not exist.
[25/Dec/2017 21:26:16] ERROR [django.request:256] Internal Server Error: /explore/get_results_by_instance_keyword
Traceback (most recent call last):
  File "/home/mdcs/anaconda2/lib/python2.7/site-packages/django/core/handlers/base.py", line 132, in get_response
    response = wrapped_callback(request, *callback_args, **callback_kwargs)
  File "/home/mdcs/Documents/MDCS-stable/explore/ajax.py", line 468, in get_results_by_instance_keyword
    temp1=get_result_list(instanceResults,request)
  File "/home/mdcs/Documents/MDCS-stable/explore/ajax.py", line 534, in get_result_list
    data = dataProfile.objects.get(xmlData=temp_result["_id"])
  File "/home/mdcs/anaconda2/lib/python2.7/site-packages/django/db/models/manager.py", line 127, in manager_method
    return getattr(self.get_queryset(), name)(*args, **kwargs)
  File "/home/mdcs/anaconda2/lib/python2.7/site-packages/django/db/models/query.py", line 334, in get
    self.model._meta.object_name
DoesNotExist: dataProfile matching query does not exist.
[25/Dec/2017 21:26:18] ERROR [django.request:256] Internal Server Error: /explore/get_results_by_instance_keyword
Traceback (most recent call last):
  File "/home/mdcs/anaconda2/lib/python2.7/site-packages/django/core/handlers/base.py", line 132, in get_response
    response = wrapped_callback(request, *callback_args, **callback_kwargs)
  File "/home/mdcs/Documents/MDCS-stable/explore/ajax.py", line 468, in get_results_by_instance_keyword
    temp1=get_result_list(instanceResults,request)
  File "/home/mdcs/Documents/MDCS-stable/explore/ajax.py", line 534, in get_result_list
    data = dataProfile.objects.get(xmlData=temp_result["_id"])
  File "/home/mdcs/anaconda2/lib/python2.7/site-packages/django/db/models/manager.py", line 127, in manager_method
    return getattr(self.get_queryset(), name)(*args, **kwargs)
  File "/home/mdcs/anaconda2/lib/python2.7/site-packages/django/db/models/query.py", line 334, in get
    self.model._meta.object_name
DoesNotExist: dataProfile matching query does not exist.
[25/Dec/2017 21:29:56] ERROR [django.request:256] Internal Server Error: /explore/get_results_by_instance_keyword
Traceback (most recent call last):
  File "/home/mdcs/anaconda2/lib/python2.7/site-packages/django/core/handlers/base.py", line 132, in get_response
    response = wrapped_callback(request, *callback_args, **callback_kwargs)
  File "/home/mdcs/Documents/MDCS-stable/explore/ajax.py", line 468, in get_results_by_instance_keyword
    temp1=get_result_list(instanceResults,request)
  File "/home/mdcs/Documents/MDCS-stable/explore/ajax.py", line 534, in get_result_list
    data = dataProfile.objects.get(xmlData=temp_result["_id"])
  File "/home/mdcs/anaconda2/lib/python2.7/site-packages/django/db/models/manager.py", line 127, in manager_method
    return getattr(self.get_queryset(), name)(*args, **kwargs)
  File "/home/mdcs/anaconda2/lib/python2.7/site-packages/django/db/models/query.py", line 334, in get
    self.model._meta.object_name
DoesNotExist: dataProfile matching query does not exist.
[25/Dec/2017 21:29:59] ERROR [django.request:256] Internal Server Error: /explore/get_results_by_instance_keyword
Traceback (most recent call last):
  File "/home/mdcs/anaconda2/lib/python2.7/site-packages/django/core/handlers/base.py", line 132, in get_response
    response = wrapped_callback(request, *callback_args, **callback_kwargs)
  File "/home/mdcs/Documents/MDCS-stable/explore/ajax.py", line 468, in get_results_by_instance_keyword
    temp1=get_result_list(instanceResults,request)
  File "/home/mdcs/Documents/MDCS-stable/explore/ajax.py", line 534, in get_result_list
    data = dataProfile.objects.get(xmlData=temp_result["_id"])
  File "/home/mdcs/anaconda2/lib/python2.7/site-packages/django/db/models/manager.py", line 127, in manager_method
    return getattr(self.get_queryset(), name)(*args, **kwargs)
  File "/home/mdcs/anaconda2/lib/python2.7/site-packages/django/db/models/query.py", line 334, in get
    self.model._meta.object_name
DoesNotExist: dataProfile matching query does not exist.
[25/Dec/2017 21:31:32] ERROR [django.request:256] Internal Server Error: /explore/get_results_by_instance_keyword
Traceback (most recent call last):
  File "/home/mdcs/anaconda2/lib/python2.7/site-packages/django/core/handlers/base.py", line 132, in get_response
    response = wrapped_callback(request, *callback_args, **callback_kwargs)
  File "/home/mdcs/Documents/MDCS-stable/explore/ajax.py", line 468, in get_results_by_instance_keyword
    temp1=get_result_list(instanceResults,request)
  File "/home/mdcs/Documents/MDCS-stable/explore/ajax.py", line 535, in get_result_list
    data = dataProfile.objects.get(xmlData=temp_result["_id"])
  File "/home/mdcs/anaconda2/lib/python2.7/site-packages/django/db/models/manager.py", line 127, in manager_method
    return getattr(self.get_queryset(), name)(*args, **kwargs)
  File "/home/mdcs/anaconda2/lib/python2.7/site-packages/django/db/models/query.py", line 334, in get
    self.model._meta.object_name
DoesNotExist: dataProfile matching query does not exist.
[25/Dec/2017 21:31:34] ERROR [django.request:256] Internal Server Error: /explore/get_results_by_instance_keyword
Traceback (most recent call last):
  File "/home/mdcs/anaconda2/lib/python2.7/site-packages/django/core/handlers/base.py", line 132, in get_response
    response = wrapped_callback(request, *callback_args, **callback_kwargs)
  File "/home/mdcs/Documents/MDCS-stable/explore/ajax.py", line 468, in get_results_by_instance_keyword
    temp1=get_result_list(instanceResults,request)
  File "/home/mdcs/Documents/MDCS-stable/explore/ajax.py", line 535, in get_result_list
    data = dataProfile.objects.get(xmlData=temp_result["_id"])
  File "/home/mdcs/anaconda2/lib/python2.7/site-packages/django/db/models/manager.py", line 127, in manager_method
    return getattr(self.get_queryset(), name)(*args, **kwargs)
  File "/home/mdcs/anaconda2/lib/python2.7/site-packages/django/db/models/query.py", line 334, in get
    self.model._meta.object_name
DoesNotExist: dataProfile matching query does not exist.
[25/Dec/2017 21:37:04] ERROR [django.request:256] Internal Server Error: /explore/get_results_by_instance_keyword
Traceback (most recent call last):
  File "/home/mdcs/anaconda2/lib/python2.7/site-packages/django/core/handlers/base.py", line 132, in get_response
    response = wrapped_callback(request, *callback_args, **callback_kwargs)
  File "/home/mdcs/Documents/MDCS-stable/explore/ajax.py", line 468, in get_results_by_instance_keyword
    temp1=get_result_list(instanceResults,request)
  File "/home/mdcs/Documents/MDCS-stable/explore/ajax.py", line 533, in get_result_list
    print 'before for instanceResults len = ' + len(instanceResults)
TypeError: cannot concatenate 'str' and 'int' objects
[25/Dec/2017 21:37:08] ERROR [django.request:256] Internal Server Error: /explore/get_results_by_instance_keyword
Traceback (most recent call last):
  File "/home/mdcs/anaconda2/lib/python2.7/site-packages/django/core/handlers/base.py", line 132, in get_response
    response = wrapped_callback(request, *callback_args, **callback_kwargs)
  File "/home/mdcs/Documents/MDCS-stable/explore/ajax.py", line 468, in get_results_by_instance_keyword
    temp1=get_result_list(instanceResults,request)
  File "/home/mdcs/Documents/MDCS-stable/explore/ajax.py", line 533, in get_result_list
    print 'before for instanceResults len = ' + len(instanceResults)
TypeError: cannot concatenate 'str' and 'int' objects
[25/Dec/2017 21:39:42] ERROR [django.request:256] Internal Server Error: /explore/get_results_by_instance_keyword
Traceback (most recent call last):
  File "/home/mdcs/anaconda2/lib/python2.7/site-packages/django/core/handlers/base.py", line 132, in get_response
    response = wrapped_callback(request, *callback_args, **callback_kwargs)
  File "/home/mdcs/Documents/MDCS-stable/explore/ajax.py", line 468, in get_results_by_instance_keyword
    temp1=get_result_list(instanceResults,request)
  File "/home/mdcs/Documents/MDCS-stable/explore/ajax.py", line 534, in get_result_list
    print 'before for instanceResults len = ' + len(instanceResults)
TypeError: cannot concatenate 'str' and 'int' objects
[25/Dec/2017 21:39:45] ERROR [django.request:256] Internal Server Error: /explore/get_results_by_instance_keyword
Traceback (most recent call last):
  File "/home/mdcs/anaconda2/lib/python2.7/site-packages/django/core/handlers/base.py", line 132, in get_response
    response = wrapped_callback(request, *callback_args, **callback_kwargs)
  File "/home/mdcs/Documents/MDCS-stable/explore/ajax.py", line 468, in get_results_by_instance_keyword
    temp1=get_result_list(instanceResults,request)
  File "/home/mdcs/Documents/MDCS-stable/explore/ajax.py", line 534, in get_result_list
    print 'before for instanceResults len = ' + len(instanceResults)
TypeError: cannot concatenate 'str' and 'int' objects
[25/Dec/2017 21:40:19] ERROR [django.request:256] Internal Server Error: /explore/get_results_by_instance_keyword
Traceback (most recent call last):
  File "/home/mdcs/anaconda2/lib/python2.7/site-packages/django/core/handlers/base.py", line 132, in get_response
    response = wrapped_callback(request, *callback_args, **callback_kwargs)
  File "/home/mdcs/Documents/MDCS-stable/explore/ajax.py", line 468, in get_results_by_instance_keyword
    temp1=get_result_list(instanceResults,request)
  File "/home/mdcs/Documents/MDCS-stable/explore/ajax.py", line 534, in get_result_list
    print 'before for instanceResults len = ' + len(instanceResults)
TypeError: cannot concatenate 'str' and 'int' objects
[25/Dec/2017 21:42:12] ERROR [django.request:256] Internal Server Error: /explore/get_results_by_instance_keyword
Traceback (most recent call last):
  File "/home/mdcs/anaconda2/lib/python2.7/site-packages/django/core/handlers/base.py", line 132, in get_response
    response = wrapped_callback(request, *callback_args, **callback_kwargs)
  File "/home/mdcs/Documents/MDCS-stable/explore/ajax.py", line 468, in get_results_by_instance_keyword
    temp1=get_result_list(instanceResults,request)
  File "/home/mdcs/Documents/MDCS-stable/explore/ajax.py", line 532, in get_result_list
    print 'before for instanceResults len = ' + len(instanceResults)
TypeError: cannot concatenate 'str' and 'int' objects
[25/Dec/2017 21:42:27] ERROR [django.request:256] Internal Server Error: /explore/get_results_by_instance_keyword
Traceback (most recent call last):
  File "/home/mdcs/anaconda2/lib/python2.7/site-packages/django/core/handlers/base.py", line 132, in get_response
    response = wrapped_callback(request, *callback_args, **callback_kwargs)
  File "/home/mdcs/Documents/MDCS-stable/explore/ajax.py", line 468, in get_results_by_instance_keyword
    temp1=get_result_list(instanceResults,request)
  File "/home/mdcs/Documents/MDCS-stable/explore/ajax.py", line 532, in get_result_list
    print 'before for instanceResults len = ' + len(instanceResults)
TypeError: cannot concatenate 'str' and 'int' objects
[25/Dec/2017 21:45:18] ERROR [django.request:256] Internal Server Error: /explore/get_results_by_instance_keyword
Traceback (most recent call last):
  File "/home/mdcs/anaconda2/lib/python2.7/site-packages/django/core/handlers/base.py", line 132, in get_response
    response = wrapped_callback(request, *callback_args, **callback_kwargs)
  File "/home/mdcs/Documents/MDCS-stable/explore/ajax.py", line 468, in get_results_by_instance_keyword
    temp1=get_result_list(instanceResults,request)
  File "/home/mdcs/Documents/MDCS-stable/explore/ajax.py", line 532, in get_result_list
    print 'before for instanceResults len = ' + len(instanceResults)
TypeError: cannot concatenate 'str' and 'int' objects
[25/Dec/2017 21:45:20] ERROR [django.request:256] Internal Server Error: /explore/get_results_by_instance_keyword
Traceback (most recent call last):
  File "/home/mdcs/anaconda2/lib/python2.7/site-packages/django/core/handlers/base.py", line 132, in get_response
    response = wrapped_callback(request, *callback_args, **callback_kwargs)
  File "/home/mdcs/Documents/MDCS-stable/explore/ajax.py", line 468, in get_results_by_instance_keyword
    temp1=get_result_list(instanceResults,request)
  File "/home/mdcs/Documents/MDCS-stable/explore/ajax.py", line 532, in get_result_list
    print 'before for instanceResults len = ' + len(instanceResults)
TypeError: cannot concatenate 'str' and 'int' objects
[26/Dec/2017 00:51:57] ERROR [django.request:256] Internal Server Error: /explore/get_results_by_instance_keyword
Traceback (most recent call last):
  File "/home/mdcs/anaconda2/lib/python2.7/site-packages/django/core/handlers/base.py", line 132, in get_response
    response = wrapped_callback(request, *callback_args, **callback_kwargs)
  File "/home/mdcs/Documents/MDCS-stable/explore/ajax.py", line 468, in get_results_by_instance_keyword
    temp1=get_result_list(instanceResults,request)
  File "/home/mdcs/Documents/MDCS-stable/explore/ajax.py", line 536, in get_result_list
    data = dataProfile.objects.get(xmlData=temp_result["_id"])
  File "/home/mdcs/anaconda2/lib/python2.7/site-packages/django/db/models/manager.py", line 127, in manager_method
    return getattr(self.get_queryset(), name)(*args, **kwargs)
  File "/home/mdcs/anaconda2/lib/python2.7/site-packages/django/db/models/query.py", line 334, in get
    self.model._meta.object_name
DoesNotExist: dataProfile matching query does not exist.
[26/Dec/2017 00:52:02] ERROR [django.request:256] Internal Server Error: /explore/get_results_by_instance_keyword
Traceback (most recent call last):
  File "/home/mdcs/anaconda2/lib/python2.7/site-packages/django/core/handlers/base.py", line 132, in get_response
    response = wrapped_callback(request, *callback_args, **callback_kwargs)
  File "/home/mdcs/Documents/MDCS-stable/explore/ajax.py", line 468, in get_results_by_instance_keyword
    temp1=get_result_list(instanceResults,request)
  File "/home/mdcs/Documents/MDCS-stable/explore/ajax.py", line 536, in get_result_list
    data = dataProfile.objects.get(xmlData=temp_result["_id"])
  File "/home/mdcs/anaconda2/lib/python2.7/site-packages/django/db/models/manager.py", line 127, in manager_method
    return getattr(self.get_queryset(), name)(*args, **kwargs)
  File "/home/mdcs/anaconda2/lib/python2.7/site-packages/django/db/models/query.py", line 334, in get
    self.model._meta.object_name
DoesNotExist: dataProfile matching query does not exist.
[26/Dec/2017 00:54:37] ERROR [django.request:256] Internal Server Error: /explore/get_results_by_instance_keyword
Traceback (most recent call last):
  File "/home/mdcs/anaconda2/lib/python2.7/site-packages/django/core/handlers/base.py", line 132, in get_response
    response = wrapped_callback(request, *callback_args, **callback_kwargs)
  File "/home/mdcs/Documents/MDCS-stable/explore/ajax.py", line 468, in get_results_by_instance_keyword
    temp1=get_result_list(instanceResults,request)
  File "/home/mdcs/Documents/MDCS-stable/explore/ajax.py", line 536, in get_result_list
    data = dataProfile.objects.get(xmlData=temp_result["_id"])
  File "/home/mdcs/anaconda2/lib/python2.7/site-packages/django/db/models/manager.py", line 127, in manager_method
    return getattr(self.get_queryset(), name)(*args, **kwargs)
  File "/home/mdcs/anaconda2/lib/python2.7/site-packages/django/db/models/query.py", line 334, in get
    self.model._meta.object_name
DoesNotExist: dataProfile matching query does not exist.
[26/Dec/2017 00:54:39] ERROR [django.request:256] Internal Server Error: /explore/get_results_by_instance_keyword
Traceback (most recent call last):
  File "/home/mdcs/anaconda2/lib/python2.7/site-packages/django/core/handlers/base.py", line 132, in get_response
    response = wrapped_callback(request, *callback_args, **callback_kwargs)
  File "/home/mdcs/Documents/MDCS-stable/explore/ajax.py", line 468, in get_results_by_instance_keyword
    temp1=get_result_list(instanceResults,request)
  File "/home/mdcs/Documents/MDCS-stable/explore/ajax.py", line 536, in get_result_list
    data = dataProfile.objects.get(xmlData=temp_result["_id"])
  File "/home/mdcs/anaconda2/lib/python2.7/site-packages/django/db/models/manager.py", line 127, in manager_method
    return getattr(self.get_queryset(), name)(*args, **kwargs)
  File "/home/mdcs/anaconda2/lib/python2.7/site-packages/django/db/models/query.py", line 334, in get
    self.model._meta.object_name
DoesNotExist: dataProfile matching query does not exist.
[26/Dec/2017 00:57:52] ERROR [django.request:256] Internal Server Error: /explore/get_results_by_instance_keyword
Traceback (most recent call last):
  File "/home/mdcs/anaconda2/lib/python2.7/site-packages/django/core/handlers/base.py", line 132, in get_response
    response = wrapped_callback(request, *callback_args, **callback_kwargs)
  File "/home/mdcs/Documents/MDCS-stable/explore/ajax.py", line 468, in get_results_by_instance_keyword
    temp1=get_result_list(instanceResults,request)
  File "/home/mdcs/Documents/MDCS-stable/explore/ajax.py", line 536, in get_result_list
    data = dataProfile.objects.get(xmlData=temp_result["_id"])
  File "/home/mdcs/anaconda2/lib/python2.7/site-packages/django/db/models/manager.py", line 127, in manager_method
    return getattr(self.get_queryset(), name)(*args, **kwargs)
  File "/home/mdcs/anaconda2/lib/python2.7/site-packages/django/db/models/query.py", line 334, in get
    self.model._meta.object_name
DoesNotExist: dataProfile matching query does not exist.
[26/Dec/2017 00:58:01] ERROR [django.request:256] Internal Server Error: /explore/get_results_by_instance_keyword
Traceback (most recent call last):
  File "/home/mdcs/anaconda2/lib/python2.7/site-packages/django/core/handlers/base.py", line 132, in get_response
    response = wrapped_callback(request, *callback_args, **callback_kwargs)
  File "/home/mdcs/Documents/MDCS-stable/explore/ajax.py", line 468, in get_results_by_instance_keyword
    temp1=get_result_list(instanceResults,request)
  File "/home/mdcs/Documents/MDCS-stable/explore/ajax.py", line 536, in get_result_list
    data = dataProfile.objects.get(xmlData=temp_result["_id"])
  File "/home/mdcs/anaconda2/lib/python2.7/site-packages/django/db/models/manager.py", line 127, in manager_method
    return getattr(self.get_queryset(), name)(*args, **kwargs)
  File "/home/mdcs/anaconda2/lib/python2.7/site-packages/django/db/models/query.py", line 334, in get
    self.model._meta.object_name
DoesNotExist: dataProfile matching query does not exist.
[26/Dec/2017 00:59:48] ERROR [django.request:256] Internal Server Error: /explore/get_results_by_instance_keyword
Traceback (most recent call last):
  File "/home/mdcs/anaconda2/lib/python2.7/site-packages/django/core/handlers/base.py", line 132, in get_response
    response = wrapped_callback(request, *callback_args, **callback_kwargs)
  File "/home/mdcs/Documents/MDCS-stable/explore/ajax.py", line 468, in get_results_by_instance_keyword
    temp1=get_result_list(instanceResults,request)
  File "/home/mdcs/Documents/MDCS-stable/explore/ajax.py", line 536, in get_result_list
    data = dataProfile.objects.get(xmlData=temp_result["_id"])
  File "/home/mdcs/anaconda2/lib/python2.7/site-packages/django/db/models/manager.py", line 127, in manager_method
    return getattr(self.get_queryset(), name)(*args, **kwargs)
  File "/home/mdcs/anaconda2/lib/python2.7/site-packages/django/db/models/query.py", line 334, in get
    self.model._meta.object_name
DoesNotExist: dataProfile matching query does not exist.
[26/Dec/2017 00:59:50] ERROR [django.request:256] Internal Server Error: /explore/get_results_by_instance_keyword
Traceback (most recent call last):
  File "/home/mdcs/anaconda2/lib/python2.7/site-packages/django/core/handlers/base.py", line 132, in get_response
    response = wrapped_callback(request, *callback_args, **callback_kwargs)
  File "/home/mdcs/Documents/MDCS-stable/explore/ajax.py", line 468, in get_results_by_instance_keyword
    temp1=get_result_list(instanceResults,request)
  File "/home/mdcs/Documents/MDCS-stable/explore/ajax.py", line 536, in get_result_list
    data = dataProfile.objects.get(xmlData=temp_result["_id"])
  File "/home/mdcs/anaconda2/lib/python2.7/site-packages/django/db/models/manager.py", line 127, in manager_method
    return getattr(self.get_queryset(), name)(*args, **kwargs)
  File "/home/mdcs/anaconda2/lib/python2.7/site-packages/django/db/models/query.py", line 334, in get
    self.model._meta.object_name
DoesNotExist: dataProfile matching query does not exist.
[26/Dec/2017 01:33:45] ERROR [django.request:256] Internal Server Error: /explore/get_results_by_instance_keyword
Traceback (most recent call last):
  File "/home/mdcs/anaconda2/lib/python2.7/site-packages/django/core/handlers/base.py", line 132, in get_response
    response = wrapped_callback(request, *callback_args, **callback_kwargs)
  File "/home/mdcs/Documents/MDCS-stable/explore/ajax.py", line 468, in get_results_by_instance_keyword
    temp1=get_result_list(instanceResults,request)
  File "/home/mdcs/Documents/MDCS-stable/explore/ajax.py", line 536, in get_result_list
    data = dataProfile.objects.get(xmlData=temp_result["_id"])
  File "/home/mdcs/anaconda2/lib/python2.7/site-packages/django/db/models/manager.py", line 127, in manager_method
    return getattr(self.get_queryset(), name)(*args, **kwargs)
  File "/home/mdcs/anaconda2/lib/python2.7/site-packages/django/db/models/query.py", line 334, in get
    self.model._meta.object_name
DoesNotExist: dataProfile matching query does not exist.
[26/Dec/2017 01:33:47] ERROR [django.request:256] Internal Server Error: /explore/get_results_by_instance_keyword
Traceback (most recent call last):
  File "/home/mdcs/anaconda2/lib/python2.7/site-packages/django/core/handlers/base.py", line 132, in get_response
    response = wrapped_callback(request, *callback_args, **callback_kwargs)
  File "/home/mdcs/Documents/MDCS-stable/explore/ajax.py", line 468, in get_results_by_instance_keyword
    temp1=get_result_list(instanceResults,request)
  File "/home/mdcs/Documents/MDCS-stable/explore/ajax.py", line 536, in get_result_list
    data = dataProfile.objects.get(xmlData=temp_result["_id"])
  File "/home/mdcs/anaconda2/lib/python2.7/site-packages/django/db/models/manager.py", line 127, in manager_method
    return getattr(self.get_queryset(), name)(*args, **kwargs)
  File "/home/mdcs/anaconda2/lib/python2.7/site-packages/django/db/models/query.py", line 334, in get
    self.model._meta.object_name
DoesNotExist: dataProfile matching query does not exist.
[26/Dec/2017 01:37:01] ERROR [django.request:256] Internal Server Error: /explore/get_results_by_instance_keyword
Traceback (most recent call last):
  File "/home/mdcs/anaconda2/lib/python2.7/site-packages/django/core/handlers/base.py", line 132, in get_response
    response = wrapped_callback(request, *callback_args, **callback_kwargs)
  File "/home/mdcs/Documents/MDCS-stable/explore/ajax.py", line 468, in get_results_by_instance_keyword
    temp1=get_result_list(instanceResults,request)
  File "/home/mdcs/Documents/MDCS-stable/explore/ajax.py", line 537, in get_result_list
    data = dataProfile.objects.get(xmlData=temp_result["_id"])
  File "/home/mdcs/anaconda2/lib/python2.7/site-packages/django/db/models/manager.py", line 127, in manager_method
    return getattr(self.get_queryset(), name)(*args, **kwargs)
  File "/home/mdcs/anaconda2/lib/python2.7/site-packages/django/db/models/query.py", line 334, in get
    self.model._meta.object_name
DoesNotExist: dataProfile matching query does not exist.
[26/Dec/2017 01:37:05] ERROR [django.request:256] Internal Server Error: /explore/get_results_by_instance_keyword
Traceback (most recent call last):
  File "/home/mdcs/anaconda2/lib/python2.7/site-packages/django/core/handlers/base.py", line 132, in get_response
    response = wrapped_callback(request, *callback_args, **callback_kwargs)
  File "/home/mdcs/Documents/MDCS-stable/explore/ajax.py", line 468, in get_results_by_instance_keyword
    temp1=get_result_list(instanceResults,request)
  File "/home/mdcs/Documents/MDCS-stable/explore/ajax.py", line 537, in get_result_list
    data = dataProfile.objects.get(xmlData=temp_result["_id"])
  File "/home/mdcs/anaconda2/lib/python2.7/site-packages/django/db/models/manager.py", line 127, in manager_method
    return getattr(self.get_queryset(), name)(*args, **kwargs)
  File "/home/mdcs/anaconda2/lib/python2.7/site-packages/django/db/models/query.py", line 334, in get
    self.model._meta.object_name
DoesNotExist: dataProfile matching query does not exist.
[26/Dec/2017 01:45:59] ERROR [django.request:256] Internal Server Error: /explore/get_results_by_instance_keyword
Traceback (most recent call last):
  File "/home/mdcs/anaconda2/lib/python2.7/site-packages/django/core/handlers/base.py", line 132, in get_response
    response = wrapped_callback(request, *callback_args, **callback_kwargs)
  File "/home/mdcs/Documents/MDCS-stable/explore/ajax.py", line 468, in get_results_by_instance_keyword
    temp1=get_result_list(instanceResults,request)
  File "/home/mdcs/Documents/MDCS-stable/explore/ajax.py", line 537, in get_result_list
    data = dataProfile.objects.get(xmlData=temp_result["_id"])
  File "/home/mdcs/anaconda2/lib/python2.7/site-packages/django/db/models/manager.py", line 127, in manager_method
    return getattr(self.get_queryset(), name)(*args, **kwargs)
  File "/home/mdcs/anaconda2/lib/python2.7/site-packages/django/db/models/query.py", line 334, in get
    self.model._meta.object_name
DoesNotExist: dataProfile matching query does not exist.
[26/Dec/2017 01:46:01] ERROR [django.request:256] Internal Server Error: /explore/get_results_by_instance_keyword
Traceback (most recent call last):
  File "/home/mdcs/anaconda2/lib/python2.7/site-packages/django/core/handlers/base.py", line 132, in get_response
    response = wrapped_callback(request, *callback_args, **callback_kwargs)
  File "/home/mdcs/Documents/MDCS-stable/explore/ajax.py", line 468, in get_results_by_instance_keyword
    temp1=get_result_list(instanceResults,request)
  File "/home/mdcs/Documents/MDCS-stable/explore/ajax.py", line 537, in get_result_list
    data = dataProfile.objects.get(xmlData=temp_result["_id"])
  File "/home/mdcs/anaconda2/lib/python2.7/site-packages/django/db/models/manager.py", line 127, in manager_method
    return getattr(self.get_queryset(), name)(*args, **kwargs)
  File "/home/mdcs/anaconda2/lib/python2.7/site-packages/django/db/models/query.py", line 334, in get
    self.model._meta.object_name
DoesNotExist: dataProfile matching query does not exist.
[27/Dec/2017 02:12:48] ERROR [django.request:256] Internal Server Error: /explore/get_results_by_instance_keyword
Traceback (most recent call last):
  File "/home/mdcs/anaconda2/lib/python2.7/site-packages/django/core/handlers/base.py", line 132, in get_response
    response = wrapped_callback(request, *callback_args, **callback_kwargs)
  File "/home/mdcs/Documents/MDCS-stable/explore/ajax.py", line 468, in get_results_by_instance_keyword
    temp1=get_result_list(instanceResults,request)
  File "/home/mdcs/Documents/MDCS-stable/explore/ajax.py", line 536, in get_result_list
    data = dataProfile.objects.get(xmlData=temp_result["_id"])
  File "/home/mdcs/anaconda2/lib/python2.7/site-packages/django/db/models/manager.py", line 127, in manager_method
    return getattr(self.get_queryset(), name)(*args, **kwargs)
  File "/home/mdcs/anaconda2/lib/python2.7/site-packages/django/db/models/query.py", line 334, in get
    self.model._meta.object_name
DoesNotExist: dataProfile matching query does not exist.
[27/Dec/2017 02:13:26] ERROR [django.request:256] Internal Server Error: /explore/get_results_by_instance_keyword
Traceback (most recent call last):
  File "/home/mdcs/anaconda2/lib/python2.7/site-packages/django/core/handlers/base.py", line 132, in get_response
    response = wrapped_callback(request, *callback_args, **callback_kwargs)
  File "/home/mdcs/Documents/MDCS-stable/explore/ajax.py", line 468, in get_results_by_instance_keyword
    temp1=get_result_list(instanceResults,request)
  File "/home/mdcs/Documents/MDCS-stable/explore/ajax.py", line 536, in get_result_list
    data = dataProfile.objects.get(xmlData=temp_result["_id"])
  File "/home/mdcs/anaconda2/lib/python2.7/site-packages/django/db/models/manager.py", line 127, in manager_method
    return getattr(self.get_queryset(), name)(*args, **kwargs)
  File "/home/mdcs/anaconda2/lib/python2.7/site-packages/django/db/models/query.py", line 334, in get
    self.model._meta.object_name
DoesNotExist: dataProfile matching query does not exist.
[27/Dec/2017 02:13:35] ERROR [django.request:256] Internal Server Error: /explore/get_results_by_instance_keyword
Traceback (most recent call last):
  File "/home/mdcs/anaconda2/lib/python2.7/site-packages/django/core/handlers/base.py", line 132, in get_response
    response = wrapped_callback(request, *callback_args, **callback_kwargs)
  File "/home/mdcs/Documents/MDCS-stable/explore/ajax.py", line 468, in get_results_by_instance_keyword
    temp1=get_result_list(instanceResults,request)
  File "/home/mdcs/Documents/MDCS-stable/explore/ajax.py", line 536, in get_result_list
    data = dataProfile.objects.get(xmlData=temp_result["_id"])
  File "/home/mdcs/anaconda2/lib/python2.7/site-packages/django/db/models/manager.py", line 127, in manager_method
    return getattr(self.get_queryset(), name)(*args, **kwargs)
  File "/home/mdcs/anaconda2/lib/python2.7/site-packages/django/db/models/query.py", line 334, in get
    self.model._meta.object_name
DoesNotExist: dataProfile matching query does not exist.
[27/Dec/2017 02:22:54] ERROR [django.request:256] Internal Server Error: /explore/get_results_by_instance_keyword
Traceback (most recent call last):
  File "/home/mdcs/anaconda2/lib/python2.7/site-packages/django/core/handlers/base.py", line 132, in get_response
    response = wrapped_callback(request, *callback_args, **callback_kwargs)
  File "/home/mdcs/Documents/MDCS-stable/explore/ajax.py", line 468, in get_results_by_instance_keyword
    temp1=get_result_list(instanceResults,request)
  File "/home/mdcs/Documents/MDCS-stable/explore/ajax.py", line 536, in get_result_list
    data = dataProfile.objects.get(xmlData=temp_result["_id"])
  File "/home/mdcs/anaconda2/lib/python2.7/site-packages/django/db/models/manager.py", line 127, in manager_method
    return getattr(self.get_queryset(), name)(*args, **kwargs)
  File "/home/mdcs/anaconda2/lib/python2.7/site-packages/django/db/models/query.py", line 334, in get
    self.model._meta.object_name
DoesNotExist: dataProfile matching query does not exist.
[27/Dec/2017 02:23:04] ERROR [django.request:256] Internal Server Error: /explore/get_results_by_instance_keyword
Traceback (most recent call last):
  File "/home/mdcs/anaconda2/lib/python2.7/site-packages/django/core/handlers/base.py", line 132, in get_response
    response = wrapped_callback(request, *callback_args, **callback_kwargs)
  File "/home/mdcs/Documents/MDCS-stable/explore/ajax.py", line 468, in get_results_by_instance_keyword
    temp1=get_result_list(instanceResults,request)
  File "/home/mdcs/Documents/MDCS-stable/explore/ajax.py", line 536, in get_result_list
    data = dataProfile.objects.get(xmlData=temp_result["_id"])
  File "/home/mdcs/anaconda2/lib/python2.7/site-packages/django/db/models/manager.py", line 127, in manager_method
    return getattr(self.get_queryset(), name)(*args, **kwargs)
  File "/home/mdcs/anaconda2/lib/python2.7/site-packages/django/db/models/query.py", line 334, in get
    self.model._meta.object_name
DoesNotExist: dataProfile matching query does not exist.
[27/Dec/2017 02:27:22] ERROR [django.request:256] Internal Server Error: /explore/get_results_by_instance_keyword
Traceback (most recent call last):
  File "/home/mdcs/anaconda2/lib/python2.7/site-packages/django/core/handlers/base.py", line 132, in get_response
    response = wrapped_callback(request, *callback_args, **callback_kwargs)
  File "/home/mdcs/Documents/MDCS-stable/explore/ajax.py", line 468, in get_results_by_instance_keyword
    temp1=get_result_list(instanceResults,request)
  File "/home/mdcs/Documents/MDCS-stable/explore/ajax.py", line 536, in get_result_list
    data = dataProfile.objects.get(xmlData=temp_result["_id"])
  File "/home/mdcs/anaconda2/lib/python2.7/site-packages/django/db/models/manager.py", line 127, in manager_method
    return getattr(self.get_queryset(), name)(*args, **kwargs)
  File "/home/mdcs/anaconda2/lib/python2.7/site-packages/django/db/models/query.py", line 334, in get
    self.model._meta.object_name
DoesNotExist: dataProfile matching query does not exist.
[27/Dec/2017 02:27:29] ERROR [django.request:256] Internal Server Error: /explore/get_results_by_instance_keyword
Traceback (most recent call last):
  File "/home/mdcs/anaconda2/lib/python2.7/site-packages/django/core/handlers/base.py", line 132, in get_response
    response = wrapped_callback(request, *callback_args, **callback_kwargs)
  File "/home/mdcs/Documents/MDCS-stable/explore/ajax.py", line 468, in get_results_by_instance_keyword
    temp1=get_result_list(instanceResults,request)
  File "/home/mdcs/Documents/MDCS-stable/explore/ajax.py", line 536, in get_result_list
    data = dataProfile.objects.get(xmlData=temp_result["_id"])
  File "/home/mdcs/anaconda2/lib/python2.7/site-packages/django/db/models/manager.py", line 127, in manager_method
    return getattr(self.get_queryset(), name)(*args, **kwargs)
  File "/home/mdcs/anaconda2/lib/python2.7/site-packages/django/db/models/query.py", line 334, in get
    self.model._meta.object_name
DoesNotExist: dataProfile matching query does not exist.
[27/Dec/2017 02:31:19] ERROR [django.request:256] Internal Server Error: /explore/get_results_by_instance_keyword
Traceback (most recent call last):
  File "/home/mdcs/anaconda2/lib/python2.7/site-packages/django/core/handlers/base.py", line 132, in get_response
    response = wrapped_callback(request, *callback_args, **callback_kwargs)
  File "/home/mdcs/Documents/MDCS-stable/explore/ajax.py", line 469, in get_results_by_instance_keyword
    print 'len==' + len(instanceResults)
TypeError: cannot concatenate 'str' and 'int' objects
[27/Dec/2017 02:31:24] ERROR [django.request:256] Internal Server Error: /explore/get_results_by_instance_keyword
Traceback (most recent call last):
  File "/home/mdcs/anaconda2/lib/python2.7/site-packages/django/core/handlers/base.py", line 132, in get_response
    response = wrapped_callback(request, *callback_args, **callback_kwargs)
  File "/home/mdcs/Documents/MDCS-stable/explore/ajax.py", line 469, in get_results_by_instance_keyword
    print 'len==' + len(instanceResults)
TypeError: cannot concatenate 'str' and 'int' objects
[27/Dec/2017 02:35:01] ERROR [django.request:256] Internal Server Error: /explore/get_results_by_instance_keyword
Traceback (most recent call last):
  File "/home/mdcs/anaconda2/lib/python2.7/site-packages/django/core/handlers/base.py", line 132, in get_response
    response = wrapped_callback(request, *callback_args, **callback_kwargs)
  File "/home/mdcs/Documents/MDCS-stable/explore/ajax.py", line 468, in get_results_by_instance_keyword
    temp1=get_result_list(instanceResults,request)
  File "/home/mdcs/Documents/MDCS-stable/explore/ajax.py", line 536, in get_result_list
    data = dataProfile.objects.get(xmlData=temp_result["_id"])
  File "/home/mdcs/anaconda2/lib/python2.7/site-packages/django/db/models/manager.py", line 127, in manager_method
    return getattr(self.get_queryset(), name)(*args, **kwargs)
  File "/home/mdcs/anaconda2/lib/python2.7/site-packages/django/db/models/query.py", line 334, in get
    self.model._meta.object_name
DoesNotExist: dataProfile matching query does not exist.
[27/Dec/2017 03:09:57] ERROR [django.request:256] Internal Server Error: /explore/get_results_by_instance_keyword
Traceback (most recent call last):
  File "/home/mdcs/anaconda2/lib/python2.7/site-packages/django/core/handlers/base.py", line 132, in get_response
    response = wrapped_callback(request, *callback_args, **callback_kwargs)
  File "/home/mdcs/Documents/MDCS-stable/explore/ajax.py", line 468, in get_results_by_instance_keyword
    temp1=get_result_list(instanceResults,request)
  File "/home/mdcs/Documents/MDCS-stable/explore/ajax.py", line 538, in get_result_list
    data = dataProfile.objects.get(xmlData=temp_result["_id"])
  File "/home/mdcs/anaconda2/lib/python2.7/site-packages/django/db/models/manager.py", line 127, in manager_method
    return getattr(self.get_queryset(), name)(*args, **kwargs)
  File "/home/mdcs/anaconda2/lib/python2.7/site-packages/django/db/models/query.py", line 334, in get
    self.model._meta.object_name
DoesNotExist: dataProfile matching query does not exist.
[27/Dec/2017 04:40:43] ERROR [django.request:256] Internal Server Error: /explore/get_results_by_instance_keyword
Traceback (most recent call last):
  File "/home/mdcs/anaconda2/lib/python2.7/site-packages/django/core/handlers/base.py", line 132, in get_response
    response = wrapped_callback(request, *callback_args, **callback_kwargs)
  File "/home/mdcs/Documents/MDCS-stable/explore/ajax.py", line 468, in get_results_by_instance_keyword
    temp1=get_result_list(instanceResults,request)
  File "/home/mdcs/Documents/MDCS-stable/explore/ajax.py", line 538, in get_result_list
    data = dataProfile.objects.get(xmlData=temp_result["_id"])
  File "/home/mdcs/anaconda2/lib/python2.7/site-packages/django/db/models/manager.py", line 127, in manager_method
    return getattr(self.get_queryset(), name)(*args, **kwargs)
  File "/home/mdcs/anaconda2/lib/python2.7/site-packages/django/db/models/query.py", line 334, in get
    self.model._meta.object_name
DoesNotExist: dataProfile matching query does not exist.
