[23/Aug/2017 00:11:47] ERROR [django.request:256] Internal Server Error: /explore/get_results_by_instance_keyword
Traceback (most recent call last):
  File "/home/mdcs/anaconda2/lib/python2.7/site-packages/django/core/handlers/base.py", line 132, in get_response
    response = wrapped_callback(request, *callback_args, **callback_kwargs)
  File "/home/mdcs/Documents/MDCS-stable/explore/ajax.py", line 464, in get_results_by_instance_keyword
    temp1=get_result_list(instanceResults,request)
  File "/home/mdcs/Documents/MDCS-stable/explore/ajax.py", line 527, in get_result_list
    data = dataProfile.objects.get(xmlData=temp_result["_id"])
  File "/home/mdcs/anaconda2/lib/python2.7/site-packages/django/db/models/manager.py", line 127, in manager_method
    return getattr(self.get_queryset(), name)(*args, **kwargs)
  File "/home/mdcs/anaconda2/lib/python2.7/site-packages/django/db/models/query.py", line 334, in get
    self.model._meta.object_name
DoesNotExist: dataProfile matching query does not exist.
[23/Aug/2017 00:12:03] ERROR [django.request:256] Internal Server Error: /explore/get_results_by_instance_keyword
Traceback (most recent call last):
  File "/home/mdcs/anaconda2/lib/python2.7/site-packages/django/core/handlers/base.py", line 132, in get_response
    response = wrapped_callback(request, *callback_args, **callback_kwargs)
  File "/home/mdcs/Documents/MDCS-stable/explore/ajax.py", line 464, in get_results_by_instance_keyword
    temp1=get_result_list(instanceResults,request)
  File "/home/mdcs/Documents/MDCS-stable/explore/ajax.py", line 527, in get_result_list
    data = dataProfile.objects.get(xmlData=temp_result["_id"])
  File "/home/mdcs/anaconda2/lib/python2.7/site-packages/django/db/models/manager.py", line 127, in manager_method
    return getattr(self.get_queryset(), name)(*args, **kwargs)
  File "/home/mdcs/anaconda2/lib/python2.7/site-packages/django/db/models/query.py", line 334, in get
    self.model._meta.object_name
DoesNotExist: dataProfile matching query does not exist.
[23/Aug/2017 00:12:04] ERROR [django.request:256] Internal Server Error: /explore/get_results_by_instance_keyword
Traceback (most recent call last):
  File "/home/mdcs/anaconda2/lib/python2.7/site-packages/django/core/handlers/base.py", line 132, in get_response
    response = wrapped_callback(request, *callback_args, **callback_kwargs)
  File "/home/mdcs/Documents/MDCS-stable/explore/ajax.py", line 464, in get_results_by_instance_keyword
    temp1=get_result_list(instanceResults,request)
  File "/home/mdcs/Documents/MDCS-stable/explore/ajax.py", line 527, in get_result_list
    data = dataProfile.objects.get(xmlData=temp_result["_id"])
  File "/home/mdcs/anaconda2/lib/python2.7/site-packages/django/db/models/manager.py", line 127, in manager_method
    return getattr(self.get_queryset(), name)(*args, **kwargs)
  File "/home/mdcs/anaconda2/lib/python2.7/site-packages/django/db/models/query.py", line 334, in get
    self.model._meta.object_name
DoesNotExist: dataProfile matching query does not exist.
[23/Aug/2017 00:12:08] ERROR [django.request:256] Internal Server Error: /explore/get_results_by_instance_keyword
Traceback (most recent call last):
  File "/home/mdcs/anaconda2/lib/python2.7/site-packages/django/core/handlers/base.py", line 132, in get_response
    response = wrapped_callback(request, *callback_args, **callback_kwargs)
  File "/home/mdcs/Documents/MDCS-stable/explore/ajax.py", line 464, in get_results_by_instance_keyword
    temp1=get_result_list(instanceResults,request)
  File "/home/mdcs/Documents/MDCS-stable/explore/ajax.py", line 527, in get_result_list
    data = dataProfile.objects.get(xmlData=temp_result["_id"])
  File "/home/mdcs/anaconda2/lib/python2.7/site-packages/django/db/models/manager.py", line 127, in manager_method
    return getattr(self.get_queryset(), name)(*args, **kwargs)
  File "/home/mdcs/anaconda2/lib/python2.7/site-packages/django/db/models/query.py", line 334, in get
    self.model._meta.object_name
DoesNotExist: dataProfile matching query does not exist.
[25/Dec/2017 04:37:23] ERROR [django.request:256] Internal Server Error: /explore/get_results_by_instance_keyword
Traceback (most recent call last):
  File "/home/mdcs/anaconda2/lib/python2.7/site-packages/django/core/handlers/base.py", line 132, in get_response
    response = wrapped_callback(request, *callback_args, **callback_kwargs)
  File "/home/mdcs/Documents/MDCS-stable/explore/ajax.py", line 464, in get_results_by_instance_keyword
    temp1=get_result_list(instanceResults,request)
  File "/home/mdcs/Documents/MDCS-stable/explore/ajax.py", line 527, in get_result_list
    data = dataProfile.objects.get(xmlData=temp_result["_id"])
  File "/home/mdcs/anaconda2/lib/python2.7/site-packages/django/db/models/manager.py", line 127, in manager_method
    return getattr(self.get_queryset(), name)(*args, **kwargs)
  File "/home/mdcs/anaconda2/lib/python2.7/site-packages/django/db/models/query.py", line 334, in get
    self.model._meta.object_name
DoesNotExist: dataProfile matching query does not exist.
[25/Dec/2017 04:37:25] ERROR [django.request:256] Internal Server Error: /explore/get_results_by_instance_keyword
Traceback (most recent call last):
  File "/home/mdcs/anaconda2/lib/python2.7/site-packages/django/core/handlers/base.py", line 132, in get_response
    response = wrapped_callback(request, *callback_args, **callback_kwargs)
  File "/home/mdcs/Documents/MDCS-stable/explore/ajax.py", line 464, in get_results_by_instance_keyword
    temp1=get_result_list(instanceResults,request)
  File "/home/mdcs/Documents/MDCS-stable/explore/ajax.py", line 527, in get_result_list
    data = dataProfile.objects.get(xmlData=temp_result["_id"])
  File "/home/mdcs/anaconda2/lib/python2.7/site-packages/django/db/models/manager.py", line 127, in manager_method
    return getattr(self.get_queryset(), name)(*args, **kwargs)
  File "/home/mdcs/anaconda2/lib/python2.7/site-packages/django/db/models/query.py", line 334, in get
    self.model._meta.object_name
DoesNotExist: dataProfile matching query does not exist.
[25/Dec/2017 04:37:50] ERROR [django.request:256] Internal Server Error: /explore/get_results_by_instance_keyword
Traceback (most recent call last):
  File "/home/mdcs/anaconda2/lib/python2.7/site-packages/django/core/handlers/base.py", line 132, in get_response
    response = wrapped_callback(request, *callback_args, **callback_kwargs)
  File "/home/mdcs/Documents/MDCS-stable/explore/ajax.py", line 464, in get_results_by_instance_keyword
    temp1=get_result_list(instanceResults,request)
  File "/home/mdcs/Documents/MDCS-stable/explore/ajax.py", line 527, in get_result_list
    data = dataProfile.objects.get(xmlData=temp_result["_id"])
  File "/home/mdcs/anaconda2/lib/python2.7/site-packages/django/db/models/manager.py", line 127, in manager_method
    return getattr(self.get_queryset(), name)(*args, **kwargs)
  File "/home/mdcs/anaconda2/lib/python2.7/site-packages/django/db/models/query.py", line 334, in get
    self.model._meta.object_name
DoesNotExist: dataProfile matching query does not exist.
[25/Dec/2017 04:37:52] ERROR [django.request:256] Internal Server Error: /explore/get_results_by_instance_keyword
Traceback (most recent call last):
  File "/home/mdcs/anaconda2/lib/python2.7/site-packages/django/core/handlers/base.py", line 132, in get_response
    response = wrapped_callback(request, *callback_args, **callback_kwargs)
  File "/home/mdcs/Documents/MDCS-stable/explore/ajax.py", line 464, in get_results_by_instance_keyword
    temp1=get_result_list(instanceResults,request)
  File "/home/mdcs/Documents/MDCS-stable/explore/ajax.py", line 527, in get_result_list
    data = dataProfile.objects.get(xmlData=temp_result["_id"])
  File "/home/mdcs/anaconda2/lib/python2.7/site-packages/django/db/models/manager.py", line 127, in manager_method
    return getattr(self.get_queryset(), name)(*args, **kwargs)
  File "/home/mdcs/anaconda2/lib/python2.7/site-packages/django/db/models/query.py", line 334, in get
    self.model._meta.object_name
DoesNotExist: dataProfile matching query does not exist.
[25/Dec/2017 04:38:21] ERROR [django.request:256] Internal Server Error: /explore/get_results_by_instance_keyword
Traceback (most recent call last):
  File "/home/mdcs/anaconda2/lib/python2.7/site-packages/django/core/handlers/base.py", line 132, in get_response
    response = wrapped_callback(request, *callback_args, **callback_kwargs)
  File "/home/mdcs/Documents/MDCS-stable/explore/ajax.py", line 464, in get_results_by_instance_keyword
    temp1=get_result_list(instanceResults,request)
  File "/home/mdcs/Documents/MDCS-stable/explore/ajax.py", line 527, in get_result_list
    data = dataProfile.objects.get(xmlData=temp_result["_id"])
  File "/home/mdcs/anaconda2/lib/python2.7/site-packages/django/db/models/manager.py", line 127, in manager_method
    return getattr(self.get_queryset(), name)(*args, **kwargs)
  File "/home/mdcs/anaconda2/lib/python2.7/site-packages/django/db/models/query.py", line 334, in get
    self.model._meta.object_name
DoesNotExist: dataProfile matching query does not exist.
[25/Dec/2017 04:38:23] ERROR [django.request:256] Internal Server Error: /explore/get_results_by_instance_keyword
Traceback (most recent call last):
  File "/home/mdcs/anaconda2/lib/python2.7/site-packages/django/core/handlers/base.py", line 132, in get_response
    response = wrapped_callback(request, *callback_args, **callback_kwargs)
  File "/home/mdcs/Documents/MDCS-stable/explore/ajax.py", line 464, in get_results_by_instance_keyword
    temp1=get_result_list(instanceResults,request)
  File "/home/mdcs/Documents/MDCS-stable/explore/ajax.py", line 527, in get_result_list
    data = dataProfile.objects.get(xmlData=temp_result["_id"])
  File "/home/mdcs/anaconda2/lib/python2.7/site-packages/django/db/models/manager.py", line 127, in manager_method
    return getattr(self.get_queryset(), name)(*args, **kwargs)
  File "/home/mdcs/anaconda2/lib/python2.7/site-packages/django/db/models/query.py", line 334, in get
    self.model._meta.object_name
DoesNotExist: dataProfile matching query does not exist.
[25/Dec/2017 04:38:44] ERROR [django.request:256] Internal Server Error: /explore/get_results_by_instance_keyword
Traceback (most recent call last):
  File "/home/mdcs/anaconda2/lib/python2.7/site-packages/django/core/handlers/base.py", line 132, in get_response
    response = wrapped_callback(request, *callback_args, **callback_kwargs)
  File "/home/mdcs/Documents/MDCS-stable/explore/ajax.py", line 464, in get_results_by_instance_keyword
    temp1=get_result_list(instanceResults,request)
  File "/home/mdcs/Documents/MDCS-stable/explore/ajax.py", line 527, in get_result_list
    data = dataProfile.objects.get(xmlData=temp_result["_id"])
  File "/home/mdcs/anaconda2/lib/python2.7/site-packages/django/db/models/manager.py", line 127, in manager_method
    return getattr(self.get_queryset(), name)(*args, **kwargs)
  File "/home/mdcs/anaconda2/lib/python2.7/site-packages/django/db/models/query.py", line 334, in get
    self.model._meta.object_name
DoesNotExist: dataProfile matching query does not exist.
[25/Dec/2017 04:38:46] ERROR [django.request:256] Internal Server Error: /explore/get_results_by_instance_keyword
Traceback (most recent call last):
  File "/home/mdcs/anaconda2/lib/python2.7/site-packages/django/core/handlers/base.py", line 132, in get_response
    response = wrapped_callback(request, *callback_args, **callback_kwargs)
  File "/home/mdcs/Documents/MDCS-stable/explore/ajax.py", line 464, in get_results_by_instance_keyword
    temp1=get_result_list(instanceResults,request)
  File "/home/mdcs/Documents/MDCS-stable/explore/ajax.py", line 527, in get_result_list
    data = dataProfile.objects.get(xmlData=temp_result["_id"])
  File "/home/mdcs/anaconda2/lib/python2.7/site-packages/django/db/models/manager.py", line 127, in manager_method
    return getattr(self.get_queryset(), name)(*args, **kwargs)
  File "/home/mdcs/anaconda2/lib/python2.7/site-packages/django/db/models/query.py", line 334, in get
    self.model._meta.object_name
DoesNotExist: dataProfile matching query does not exist.
[25/Dec/2017 04:39:12] ERROR [django.request:256] Internal Server Error: /explore/get_results_by_instance_keyword
Traceback (most recent call last):
  File "/home/mdcs/anaconda2/lib/python2.7/site-packages/django/core/handlers/base.py", line 132, in get_response
    response = wrapped_callback(request, *callback_args, **callback_kwargs)
  File "/home/mdcs/Documents/MDCS-stable/explore/ajax.py", line 464, in get_results_by_instance_keyword
    temp1=get_result_list(instanceResults,request)
  File "/home/mdcs/Documents/MDCS-stable/explore/ajax.py", line 527, in get_result_list
    data = dataProfile.objects.get(xmlData=temp_result["_id"])
  File "/home/mdcs/anaconda2/lib/python2.7/site-packages/django/db/models/manager.py", line 127, in manager_method
    return getattr(self.get_queryset(), name)(*args, **kwargs)
  File "/home/mdcs/anaconda2/lib/python2.7/site-packages/django/db/models/query.py", line 334, in get
    self.model._meta.object_name
DoesNotExist: dataProfile matching query does not exist.
[25/Dec/2017 04:39:17] ERROR [django.request:256] Internal Server Error: /explore/get_results_by_instance_keyword
Traceback (most recent call last):
  File "/home/mdcs/anaconda2/lib/python2.7/site-packages/django/core/handlers/base.py", line 132, in get_response
    response = wrapped_callback(request, *callback_args, **callback_kwargs)
  File "/home/mdcs/Documents/MDCS-stable/explore/ajax.py", line 464, in get_results_by_instance_keyword
    temp1=get_result_list(instanceResults,request)
  File "/home/mdcs/Documents/MDCS-stable/explore/ajax.py", line 527, in get_result_list
    data = dataProfile.objects.get(xmlData=temp_result["_id"])
  File "/home/mdcs/anaconda2/lib/python2.7/site-packages/django/db/models/manager.py", line 127, in manager_method
    return getattr(self.get_queryset(), name)(*args, **kwargs)
  File "/home/mdcs/anaconda2/lib/python2.7/site-packages/django/db/models/query.py", line 334, in get
    self.model._meta.object_name
DoesNotExist: dataProfile matching query does not exist.
[25/Dec/2017 04:39:19] ERROR [django.request:256] Internal Server Error: /explore/get_results_by_instance_keyword
Traceback (most recent call last):
  File "/home/mdcs/anaconda2/lib/python2.7/site-packages/django/core/handlers/base.py", line 132, in get_response
    response = wrapped_callback(request, *callback_args, **callback_kwargs)
  File "/home/mdcs/Documents/MDCS-stable/explore/ajax.py", line 464, in get_results_by_instance_keyword
    temp1=get_result_list(instanceResults,request)
  File "/home/mdcs/Documents/MDCS-stable/explore/ajax.py", line 527, in get_result_list
    data = dataProfile.objects.get(xmlData=temp_result["_id"])
  File "/home/mdcs/anaconda2/lib/python2.7/site-packages/django/db/models/manager.py", line 127, in manager_method
    return getattr(self.get_queryset(), name)(*args, **kwargs)
  File "/home/mdcs/anaconda2/lib/python2.7/site-packages/django/db/models/query.py", line 334, in get
    self.model._meta.object_name
DoesNotExist: dataProfile matching query does not exist.
[25/Dec/2017 04:39:28] ERROR [django.request:256] Internal Server Error: /explore/get_results_by_instance_keyword
Traceback (most recent call last):
  File "/home/mdcs/anaconda2/lib/python2.7/site-packages/django/core/handlers/base.py", line 132, in get_response
    response = wrapped_callback(request, *callback_args, **callback_kwargs)
  File "/home/mdcs/Documents/MDCS-stable/explore/ajax.py", line 464, in get_results_by_instance_keyword
    temp1=get_result_list(instanceResults,request)
  File "/home/mdcs/Documents/MDCS-stable/explore/ajax.py", line 527, in get_result_list
    data = dataProfile.objects.get(xmlData=temp_result["_id"])
  File "/home/mdcs/anaconda2/lib/python2.7/site-packages/django/db/models/manager.py", line 127, in manager_method
    return getattr(self.get_queryset(), name)(*args, **kwargs)
  File "/home/mdcs/anaconda2/lib/python2.7/site-packages/django/db/models/query.py", line 334, in get
    self.model._meta.object_name
DoesNotExist: dataProfile matching query does not exist.
[25/Dec/2017 04:39:30] ERROR [django.request:256] Internal Server Error: /explore/get_results_by_instance_keyword
Traceback (most recent call last):
  File "/home/mdcs/anaconda2/lib/python2.7/site-packages/django/core/handlers/base.py", line 132, in get_response
    response = wrapped_callback(request, *callback_args, **callback_kwargs)
  File "/home/mdcs/Documents/MDCS-stable/explore/ajax.py", line 464, in get_results_by_instance_keyword
    temp1=get_result_list(instanceResults,request)
  File "/home/mdcs/Documents/MDCS-stable/explore/ajax.py", line 527, in get_result_list
    data = dataProfile.objects.get(xmlData=temp_result["_id"])
  File "/home/mdcs/anaconda2/lib/python2.7/site-packages/django/db/models/manager.py", line 127, in manager_method
    return getattr(self.get_queryset(), name)(*args, **kwargs)
  File "/home/mdcs/anaconda2/lib/python2.7/site-packages/django/db/models/query.py", line 334, in get
    self.model._meta.object_name
DoesNotExist: dataProfile matching query does not exist.
[25/Dec/2017 04:40:04] ERROR [django.request:256] Internal Server Error: /explore/get_results_by_instance_keyword
Traceback (most recent call last):
  File "/home/mdcs/anaconda2/lib/python2.7/site-packages/django/core/handlers/base.py", line 132, in get_response
    response = wrapped_callback(request, *callback_args, **callback_kwargs)
  File "/home/mdcs/Documents/MDCS-stable/explore/ajax.py", line 464, in get_results_by_instance_keyword
    temp1=get_result_list(instanceResults,request)
  File "/home/mdcs/Documents/MDCS-stable/explore/ajax.py", line 527, in get_result_list
    data = dataProfile.objects.get(xmlData=temp_result["_id"])
  File "/home/mdcs/anaconda2/lib/python2.7/site-packages/django/db/models/manager.py", line 127, in manager_method
    return getattr(self.get_queryset(), name)(*args, **kwargs)
  File "/home/mdcs/anaconda2/lib/python2.7/site-packages/django/db/models/query.py", line 334, in get
    self.model._meta.object_name
DoesNotExist: dataProfile matching query does not exist.
[25/Dec/2017 04:40:06] ERROR [django.request:256] Internal Server Error: /explore/get_results_by_instance_keyword
Traceback (most recent call last):
  File "/home/mdcs/anaconda2/lib/python2.7/site-packages/django/core/handlers/base.py", line 132, in get_response
    response = wrapped_callback(request, *callback_args, **callback_kwargs)
  File "/home/mdcs/Documents/MDCS-stable/explore/ajax.py", line 464, in get_results_by_instance_keyword
    temp1=get_result_list(instanceResults,request)
  File "/home/mdcs/Documents/MDCS-stable/explore/ajax.py", line 527, in get_result_list
    data = dataProfile.objects.get(xmlData=temp_result["_id"])
  File "/home/mdcs/anaconda2/lib/python2.7/site-packages/django/db/models/manager.py", line 127, in manager_method
    return getattr(self.get_queryset(), name)(*args, **kwargs)
  File "/home/mdcs/anaconda2/lib/python2.7/site-packages/django/db/models/query.py", line 334, in get
    self.model._meta.object_name
DoesNotExist: dataProfile matching query does not exist.
[25/Dec/2017 04:40:09] ERROR [django.request:256] Internal Server Error: /explore/get_results_by_instance_keyword
Traceback (most recent call last):
  File "/home/mdcs/anaconda2/lib/python2.7/site-packages/django/core/handlers/base.py", line 132, in get_response
    response = wrapped_callback(request, *callback_args, **callback_kwargs)
  File "/home/mdcs/Documents/MDCS-stable/explore/ajax.py", line 464, in get_results_by_instance_keyword
    temp1=get_result_list(instanceResults,request)
  File "/home/mdcs/Documents/MDCS-stable/explore/ajax.py", line 527, in get_result_list
    data = dataProfile.objects.get(xmlData=temp_result["_id"])
  File "/home/mdcs/anaconda2/lib/python2.7/site-packages/django/db/models/manager.py", line 127, in manager_method
    return getattr(self.get_queryset(), name)(*args, **kwargs)
  File "/home/mdcs/anaconda2/lib/python2.7/site-packages/django/db/models/query.py", line 334, in get
    self.model._meta.object_name
DoesNotExist: dataProfile matching query does not exist.
[25/Dec/2017 05:08:45] ERROR [django.request:256] Internal Server Error: /explore/get_results_by_instance_keyword
Traceback (most recent call last):
  File "/home/mdcs/anaconda2/lib/python2.7/site-packages/django/core/handlers/base.py", line 132, in get_response
    response = wrapped_callback(request, *callback_args, **callback_kwargs)
  File "/home/mdcs/Documents/MDCS-stable/explore/ajax.py", line 464, in get_results_by_instance_keyword
    temp1=get_result_list(instanceResults,request)
  File "/home/mdcs/Documents/MDCS-stable/explore/ajax.py", line 527, in get_result_list
    data = dataProfile.objects.get(xmlData=temp_result["_id"])
  File "/home/mdcs/anaconda2/lib/python2.7/site-packages/django/db/models/manager.py", line 127, in manager_method
    return getattr(self.get_queryset(), name)(*args, **kwargs)
  File "/home/mdcs/anaconda2/lib/python2.7/site-packages/django/db/models/query.py", line 334, in get
    self.model._meta.object_name
DoesNotExist: dataProfile matching query does not exist.
[25/Dec/2017 05:08:46] ERROR [django.request:256] Internal Server Error: /explore/get_results_by_instance_keyword
Traceback (most recent call last):
  File "/home/mdcs/anaconda2/lib/python2.7/site-packages/django/core/handlers/base.py", line 132, in get_response
    response = wrapped_callback(request, *callback_args, **callback_kwargs)
  File "/home/mdcs/Documents/MDCS-stable/explore/ajax.py", line 464, in get_results_by_instance_keyword
    temp1=get_result_list(instanceResults,request)
  File "/home/mdcs/Documents/MDCS-stable/explore/ajax.py", line 527, in get_result_list
    data = dataProfile.objects.get(xmlData=temp_result["_id"])
  File "/home/mdcs/anaconda2/lib/python2.7/site-packages/django/db/models/manager.py", line 127, in manager_method
    return getattr(self.get_queryset(), name)(*args, **kwargs)
  File "/home/mdcs/anaconda2/lib/python2.7/site-packages/django/db/models/query.py", line 334, in get
    self.model._meta.object_name
DoesNotExist: dataProfile matching query does not exist.
[25/Dec/2017 05:08:48] ERROR [django.request:256] Internal Server Error: /explore/get_results_by_instance_keyword
Traceback (most recent call last):
  File "/home/mdcs/anaconda2/lib/python2.7/site-packages/django/core/handlers/base.py", line 132, in get_response
    response = wrapped_callback(request, *callback_args, **callback_kwargs)
  File "/home/mdcs/Documents/MDCS-stable/explore/ajax.py", line 464, in get_results_by_instance_keyword
    temp1=get_result_list(instanceResults,request)
  File "/home/mdcs/Documents/MDCS-stable/explore/ajax.py", line 527, in get_result_list
    data = dataProfile.objects.get(xmlData=temp_result["_id"])
  File "/home/mdcs/anaconda2/lib/python2.7/site-packages/django/db/models/manager.py", line 127, in manager_method
    return getattr(self.get_queryset(), name)(*args, **kwargs)
  File "/home/mdcs/anaconda2/lib/python2.7/site-packages/django/db/models/query.py", line 334, in get
    self.model._meta.object_name
DoesNotExist: dataProfile matching query does not exist.
[25/Dec/2017 05:08:53] ERROR [django.request:256] Internal Server Error: /explore/get_results_by_instance_keyword
Traceback (most recent call last):
  File "/home/mdcs/anaconda2/lib/python2.7/site-packages/django/core/handlers/base.py", line 132, in get_response
    response = wrapped_callback(request, *callback_args, **callback_kwargs)
  File "/home/mdcs/Documents/MDCS-stable/explore/ajax.py", line 464, in get_results_by_instance_keyword
    temp1=get_result_list(instanceResults,request)
  File "/home/mdcs/Documents/MDCS-stable/explore/ajax.py", line 527, in get_result_list
    data = dataProfile.objects.get(xmlData=temp_result["_id"])
  File "/home/mdcs/anaconda2/lib/python2.7/site-packages/django/db/models/manager.py", line 127, in manager_method
    return getattr(self.get_queryset(), name)(*args, **kwargs)
  File "/home/mdcs/anaconda2/lib/python2.7/site-packages/django/db/models/query.py", line 334, in get
    self.model._meta.object_name
DoesNotExist: dataProfile matching query does not exist.
[25/Dec/2017 05:09:19] ERROR [django.request:256] Internal Server Error: /explore/get_results_by_instance_keyword
Traceback (most recent call last):
  File "/home/mdcs/anaconda2/lib/python2.7/site-packages/django/core/handlers/base.py", line 132, in get_response
    response = wrapped_callback(request, *callback_args, **callback_kwargs)
  File "/home/mdcs/Documents/MDCS-stable/explore/ajax.py", line 464, in get_results_by_instance_keyword
    temp1=get_result_list(instanceResults,request)
  File "/home/mdcs/Documents/MDCS-stable/explore/ajax.py", line 527, in get_result_list
    data = dataProfile.objects.get(xmlData=temp_result["_id"])
  File "/home/mdcs/anaconda2/lib/python2.7/site-packages/django/db/models/manager.py", line 127, in manager_method
    return getattr(self.get_queryset(), name)(*args, **kwargs)
  File "/home/mdcs/anaconda2/lib/python2.7/site-packages/django/db/models/query.py", line 334, in get
    self.model._meta.object_name
DoesNotExist: dataProfile matching query does not exist.
[25/Dec/2017 05:09:20] ERROR [django.request:256] Internal Server Error: /explore/get_results_by_instance_keyword
Traceback (most recent call last):
  File "/home/mdcs/anaconda2/lib/python2.7/site-packages/django/core/handlers/base.py", line 132, in get_response
    response = wrapped_callback(request, *callback_args, **callback_kwargs)
  File "/home/mdcs/Documents/MDCS-stable/explore/ajax.py", line 464, in get_results_by_instance_keyword
    temp1=get_result_list(instanceResults,request)
  File "/home/mdcs/Documents/MDCS-stable/explore/ajax.py", line 527, in get_result_list
    data = dataProfile.objects.get(xmlData=temp_result["_id"])
  File "/home/mdcs/anaconda2/lib/python2.7/site-packages/django/db/models/manager.py", line 127, in manager_method
    return getattr(self.get_queryset(), name)(*args, **kwargs)
  File "/home/mdcs/anaconda2/lib/python2.7/site-packages/django/db/models/query.py", line 334, in get
    self.model._meta.object_name
DoesNotExist: dataProfile matching query does not exist.
[25/Dec/2017 05:09:27] ERROR [django.request:256] Internal Server Error: /explore/get_results_by_instance_keyword
Traceback (most recent call last):
  File "/home/mdcs/anaconda2/lib/python2.7/site-packages/django/core/handlers/base.py", line 132, in get_response
    response = wrapped_callback(request, *callback_args, **callback_kwargs)
  File "/home/mdcs/Documents/MDCS-stable/explore/ajax.py", line 464, in get_results_by_instance_keyword
    temp1=get_result_list(instanceResults,request)
  File "/home/mdcs/Documents/MDCS-stable/explore/ajax.py", line 527, in get_result_list
    data = dataProfile.objects.get(xmlData=temp_result["_id"])
  File "/home/mdcs/anaconda2/lib/python2.7/site-packages/django/db/models/manager.py", line 127, in manager_method
    return getattr(self.get_queryset(), name)(*args, **kwargs)
  File "/home/mdcs/anaconda2/lib/python2.7/site-packages/django/db/models/query.py", line 334, in get
    self.model._meta.object_name
DoesNotExist: dataProfile matching query does not exist.
[25/Dec/2017 05:09:56] ERROR [django.request:256] Internal Server Error: /explore/get_results_by_instance_keyword
Traceback (most recent call last):
  File "/home/mdcs/anaconda2/lib/python2.7/site-packages/django/core/handlers/base.py", line 132, in get_response
    response = wrapped_callback(request, *callback_args, **callback_kwargs)
  File "/home/mdcs/Documents/MDCS-stable/explore/ajax.py", line 464, in get_results_by_instance_keyword
    temp1=get_result_list(instanceResults,request)
  File "/home/mdcs/Documents/MDCS-stable/explore/ajax.py", line 527, in get_result_list
    data = dataProfile.objects.get(xmlData=temp_result["_id"])
  File "/home/mdcs/anaconda2/lib/python2.7/site-packages/django/db/models/manager.py", line 127, in manager_method
    return getattr(self.get_queryset(), name)(*args, **kwargs)
  File "/home/mdcs/anaconda2/lib/python2.7/site-packages/django/db/models/query.py", line 334, in get
    self.model._meta.object_name
DoesNotExist: dataProfile matching query does not exist.
[25/Dec/2017 05:10:09] ERROR [django.request:256] Internal Server Error: /explore/get_results_by_instance_keyword
Traceback (most recent call last):
  File "/home/mdcs/anaconda2/lib/python2.7/site-packages/django/core/handlers/base.py", line 132, in get_response
    response = wrapped_callback(request, *callback_args, **callback_kwargs)
  File "/home/mdcs/Documents/MDCS-stable/explore/ajax.py", line 464, in get_results_by_instance_keyword
    temp1=get_result_list(instanceResults,request)
  File "/home/mdcs/Documents/MDCS-stable/explore/ajax.py", line 527, in get_result_list
    data = dataProfile.objects.get(xmlData=temp_result["_id"])
  File "/home/mdcs/anaconda2/lib/python2.7/site-packages/django/db/models/manager.py", line 127, in manager_method
    return getattr(self.get_queryset(), name)(*args, **kwargs)
  File "/home/mdcs/anaconda2/lib/python2.7/site-packages/django/db/models/query.py", line 334, in get
    self.model._meta.object_name
DoesNotExist: dataProfile matching query does not exist.
[25/Dec/2017 05:10:16] ERROR [django.request:256] Internal Server Error: /explore/get_results_by_instance_keyword
Traceback (most recent call last):
  File "/home/mdcs/anaconda2/lib/python2.7/site-packages/django/core/handlers/base.py", line 132, in get_response
    response = wrapped_callback(request, *callback_args, **callback_kwargs)
  File "/home/mdcs/Documents/MDCS-stable/explore/ajax.py", line 464, in get_results_by_instance_keyword
    temp1=get_result_list(instanceResults,request)
  File "/home/mdcs/Documents/MDCS-stable/explore/ajax.py", line 527, in get_result_list
    data = dataProfile.objects.get(xmlData=temp_result["_id"])
  File "/home/mdcs/anaconda2/lib/python2.7/site-packages/django/db/models/manager.py", line 127, in manager_method
    return getattr(self.get_queryset(), name)(*args, **kwargs)
  File "/home/mdcs/anaconda2/lib/python2.7/site-packages/django/db/models/query.py", line 334, in get
    self.model._meta.object_name
DoesNotExist: dataProfile matching query does not exist.
[25/Dec/2017 05:10:27] ERROR [django.request:256] Internal Server Error: /explore/get_results_by_instance_keyword
Traceback (most recent call last):
  File "/home/mdcs/anaconda2/lib/python2.7/site-packages/django/core/handlers/base.py", line 132, in get_response
    response = wrapped_callback(request, *callback_args, **callback_kwargs)
  File "/home/mdcs/Documents/MDCS-stable/explore/ajax.py", line 464, in get_results_by_instance_keyword
    temp1=get_result_list(instanceResults,request)
  File "/home/mdcs/Documents/MDCS-stable/explore/ajax.py", line 527, in get_result_list
    data = dataProfile.objects.get(xmlData=temp_result["_id"])
  File "/home/mdcs/anaconda2/lib/python2.7/site-packages/django/db/models/manager.py", line 127, in manager_method
    return getattr(self.get_queryset(), name)(*args, **kwargs)
  File "/home/mdcs/anaconda2/lib/python2.7/site-packages/django/db/models/query.py", line 334, in get
    self.model._meta.object_name
DoesNotExist: dataProfile matching query does not exist.
[25/Dec/2017 05:10:27] ERROR [django.request:256] Internal Server Error: /explore/get_results_by_instance_keyword
Traceback (most recent call last):
  File "/home/mdcs/anaconda2/lib/python2.7/site-packages/django/core/handlers/base.py", line 132, in get_response
    response = wrapped_callback(request, *callback_args, **callback_kwargs)
  File "/home/mdcs/Documents/MDCS-stable/explore/ajax.py", line 464, in get_results_by_instance_keyword
    temp1=get_result_list(instanceResults,request)
  File "/home/mdcs/Documents/MDCS-stable/explore/ajax.py", line 527, in get_result_list
    data = dataProfile.objects.get(xmlData=temp_result["_id"])
  File "/home/mdcs/anaconda2/lib/python2.7/site-packages/django/db/models/manager.py", line 127, in manager_method
    return getattr(self.get_queryset(), name)(*args, **kwargs)
  File "/home/mdcs/anaconda2/lib/python2.7/site-packages/django/db/models/query.py", line 334, in get
    self.model._meta.object_name
DoesNotExist: dataProfile matching query does not exist.
[25/Dec/2017 05:10:29] ERROR [django.request:256] Internal Server Error: /explore/get_results_by_instance_keyword
Traceback (most recent call last):
  File "/home/mdcs/anaconda2/lib/python2.7/site-packages/django/core/handlers/base.py", line 132, in get_response
    response = wrapped_callback(request, *callback_args, **callback_kwargs)
  File "/home/mdcs/Documents/MDCS-stable/explore/ajax.py", line 464, in get_results_by_instance_keyword
    temp1=get_result_list(instanceResults,request)
  File "/home/mdcs/Documents/MDCS-stable/explore/ajax.py", line 527, in get_result_list
    data = dataProfile.objects.get(xmlData=temp_result["_id"])
  File "/home/mdcs/anaconda2/lib/python2.7/site-packages/django/db/models/manager.py", line 127, in manager_method
    return getattr(self.get_queryset(), name)(*args, **kwargs)
  File "/home/mdcs/anaconda2/lib/python2.7/site-packages/django/db/models/query.py", line 334, in get
    self.model._meta.object_name
DoesNotExist: dataProfile matching query does not exist.
[25/Dec/2017 05:10:32] ERROR [django.request:256] Internal Server Error: /explore/get_results_by_instance_keyword
Traceback (most recent call last):
  File "/home/mdcs/anaconda2/lib/python2.7/site-packages/django/core/handlers/base.py", line 132, in get_response
    response = wrapped_callback(request, *callback_args, **callback_kwargs)
  File "/home/mdcs/Documents/MDCS-stable/explore/ajax.py", line 464, in get_results_by_instance_keyword
    temp1=get_result_list(instanceResults,request)
  File "/home/mdcs/Documents/MDCS-stable/explore/ajax.py", line 527, in get_result_list
    data = dataProfile.objects.get(xmlData=temp_result["_id"])
  File "/home/mdcs/anaconda2/lib/python2.7/site-packages/django/db/models/manager.py", line 127, in manager_method
    return getattr(self.get_queryset(), name)(*args, **kwargs)
  File "/home/mdcs/anaconda2/lib/python2.7/site-packages/django/db/models/query.py", line 334, in get
    self.model._meta.object_name
DoesNotExist: dataProfile matching query does not exist.
[25/Dec/2017 05:13:01] ERROR [django.request:256] Internal Server Error: /explore/get_results_by_instance_keyword
Traceback (most recent call last):
  File "/home/mdcs/anaconda2/lib/python2.7/site-packages/django/core/handlers/base.py", line 132, in get_response
    response = wrapped_callback(request, *callback_args, **callback_kwargs)
  File "/home/mdcs/Documents/MDCS-stable/explore/ajax.py", line 464, in get_results_by_instance_keyword
    temp1=get_result_list(instanceResults,request)
  File "/home/mdcs/Documents/MDCS-stable/explore/ajax.py", line 527, in get_result_list
    data = dataProfile.objects.get(xmlData=temp_result["_id"])
  File "/home/mdcs/anaconda2/lib/python2.7/site-packages/django/db/models/manager.py", line 127, in manager_method
    return getattr(self.get_queryset(), name)(*args, **kwargs)
  File "/home/mdcs/anaconda2/lib/python2.7/site-packages/django/db/models/query.py", line 334, in get
    self.model._meta.object_name
DoesNotExist: dataProfile matching query does not exist.
[25/Dec/2017 05:13:17] ERROR [django.request:256] Internal Server Error: /explore/get_results_by_instance_keyword
Traceback (most recent call last):
  File "/home/mdcs/anaconda2/lib/python2.7/site-packages/django/core/handlers/base.py", line 132, in get_response
    response = wrapped_callback(request, *callback_args, **callback_kwargs)
  File "/home/mdcs/Documents/MDCS-stable/explore/ajax.py", line 464, in get_results_by_instance_keyword
    temp1=get_result_list(instanceResults,request)
  File "/home/mdcs/Documents/MDCS-stable/explore/ajax.py", line 527, in get_result_list
    data = dataProfile.objects.get(xmlData=temp_result["_id"])
  File "/home/mdcs/anaconda2/lib/python2.7/site-packages/django/db/models/manager.py", line 127, in manager_method
    return getattr(self.get_queryset(), name)(*args, **kwargs)
  File "/home/mdcs/anaconda2/lib/python2.7/site-packages/django/db/models/query.py", line 334, in get
    self.model._meta.object_name
DoesNotExist: dataProfile matching query does not exist.
[25/Dec/2017 05:13:18] ERROR [django.request:256] Internal Server Error: /explore/get_results_by_instance_keyword
Traceback (most recent call last):
  File "/home/mdcs/anaconda2/lib/python2.7/site-packages/django/core/handlers/base.py", line 132, in get_response
    response = wrapped_callback(request, *callback_args, **callback_kwargs)
  File "/home/mdcs/Documents/MDCS-stable/explore/ajax.py", line 464, in get_results_by_instance_keyword
    temp1=get_result_list(instanceResults,request)
  File "/home/mdcs/Documents/MDCS-stable/explore/ajax.py", line 527, in get_result_list
    data = dataProfile.objects.get(xmlData=temp_result["_id"])
  File "/home/mdcs/anaconda2/lib/python2.7/site-packages/django/db/models/manager.py", line 127, in manager_method
    return getattr(self.get_queryset(), name)(*args, **kwargs)
  File "/home/mdcs/anaconda2/lib/python2.7/site-packages/django/db/models/query.py", line 334, in get
    self.model._meta.object_name
DoesNotExist: dataProfile matching query does not exist.
[25/Dec/2017 05:13:20] ERROR [django.request:256] Internal Server Error: /explore/get_results_by_instance_keyword
Traceback (most recent call last):
  File "/home/mdcs/anaconda2/lib/python2.7/site-packages/django/core/handlers/base.py", line 132, in get_response
    response = wrapped_callback(request, *callback_args, **callback_kwargs)
  File "/home/mdcs/Documents/MDCS-stable/explore/ajax.py", line 464, in get_results_by_instance_keyword
    temp1=get_result_list(instanceResults,request)
  File "/home/mdcs/Documents/MDCS-stable/explore/ajax.py", line 527, in get_result_list
    data = dataProfile.objects.get(xmlData=temp_result["_id"])
  File "/home/mdcs/anaconda2/lib/python2.7/site-packages/django/db/models/manager.py", line 127, in manager_method
    return getattr(self.get_queryset(), name)(*args, **kwargs)
  File "/home/mdcs/anaconda2/lib/python2.7/site-packages/django/db/models/query.py", line 334, in get
    self.model._meta.object_name
DoesNotExist: dataProfile matching query does not exist.
[25/Dec/2017 05:13:32] ERROR [django.request:256] Internal Server Error: /explore/get_results_by_instance_keyword
Traceback (most recent call last):
  File "/home/mdcs/anaconda2/lib/python2.7/site-packages/django/core/handlers/base.py", line 132, in get_response
    response = wrapped_callback(request, *callback_args, **callback_kwargs)
  File "/home/mdcs/Documents/MDCS-stable/explore/ajax.py", line 464, in get_results_by_instance_keyword
    temp1=get_result_list(instanceResults,request)
  File "/home/mdcs/Documents/MDCS-stable/explore/ajax.py", line 527, in get_result_list
    data = dataProfile.objects.get(xmlData=temp_result["_id"])
  File "/home/mdcs/anaconda2/lib/python2.7/site-packages/django/db/models/manager.py", line 127, in manager_method
    return getattr(self.get_queryset(), name)(*args, **kwargs)
  File "/home/mdcs/anaconda2/lib/python2.7/site-packages/django/db/models/query.py", line 334, in get
    self.model._meta.object_name
DoesNotExist: dataProfile matching query does not exist.
[25/Dec/2017 05:13:32] ERROR [django.request:256] Internal Server Error: /explore/get_results_by_instance_keyword
Traceback (most recent call last):
  File "/home/mdcs/anaconda2/lib/python2.7/site-packages/django/core/handlers/base.py", line 132, in get_response
    response = wrapped_callback(request, *callback_args, **callback_kwargs)
  File "/home/mdcs/Documents/MDCS-stable/explore/ajax.py", line 464, in get_results_by_instance_keyword
    temp1=get_result_list(instanceResults,request)
  File "/home/mdcs/Documents/MDCS-stable/explore/ajax.py", line 527, in get_result_list
    data = dataProfile.objects.get(xmlData=temp_result["_id"])
  File "/home/mdcs/anaconda2/lib/python2.7/site-packages/django/db/models/manager.py", line 127, in manager_method
    return getattr(self.get_queryset(), name)(*args, **kwargs)
  File "/home/mdcs/anaconda2/lib/python2.7/site-packages/django/db/models/query.py", line 334, in get
    self.model._meta.object_name
DoesNotExist: dataProfile matching query does not exist.
[25/Dec/2017 05:13:34] ERROR [django.request:256] Internal Server Error: /explore/get_results_by_instance_keyword
Traceback (most recent call last):
  File "/home/mdcs/anaconda2/lib/python2.7/site-packages/django/core/handlers/base.py", line 132, in get_response
    response = wrapped_callback(request, *callback_args, **callback_kwargs)
  File "/home/mdcs/Documents/MDCS-stable/explore/ajax.py", line 464, in get_results_by_instance_keyword
    temp1=get_result_list(instanceResults,request)
  File "/home/mdcs/Documents/MDCS-stable/explore/ajax.py", line 527, in get_result_list
    data = dataProfile.objects.get(xmlData=temp_result["_id"])
  File "/home/mdcs/anaconda2/lib/python2.7/site-packages/django/db/models/manager.py", line 127, in manager_method
    return getattr(self.get_queryset(), name)(*args, **kwargs)
  File "/home/mdcs/anaconda2/lib/python2.7/site-packages/django/db/models/query.py", line 334, in get
    self.model._meta.object_name
DoesNotExist: dataProfile matching query does not exist.
[25/Dec/2017 05:45:01] ERROR [django.request:256] Internal Server Error: /explore/get_results_by_instance_keyword
Traceback (most recent call last):
  File "/home/mdcs/anaconda2/lib/python2.7/site-packages/django/core/handlers/base.py", line 132, in get_response
    response = wrapped_callback(request, *callback_args, **callback_kwargs)
  File "/home/mdcs/Documents/MDCS-stable/explore/ajax.py", line 464, in get_results_by_instance_keyword
    temp1=get_result_list(instanceResults,request)
  File "/home/mdcs/Documents/MDCS-stable/explore/ajax.py", line 527, in get_result_list
    data = dataProfile.objects.get(xmlData=temp_result["_id"])
  File "/home/mdcs/anaconda2/lib/python2.7/site-packages/django/db/models/manager.py", line 127, in manager_method
    return getattr(self.get_queryset(), name)(*args, **kwargs)
  File "/home/mdcs/anaconda2/lib/python2.7/site-packages/django/db/models/query.py", line 334, in get
    self.model._meta.object_name
DoesNotExist: dataProfile matching query does not exist.
[25/Dec/2017 05:45:03] ERROR [django.request:256] Internal Server Error: /explore/get_results_by_instance_keyword
Traceback (most recent call last):
  File "/home/mdcs/anaconda2/lib/python2.7/site-packages/django/core/handlers/base.py", line 132, in get_response
    response = wrapped_callback(request, *callback_args, **callback_kwargs)
  File "/home/mdcs/Documents/MDCS-stable/explore/ajax.py", line 464, in get_results_by_instance_keyword
    temp1=get_result_list(instanceResults,request)
  File "/home/mdcs/Documents/MDCS-stable/explore/ajax.py", line 527, in get_result_list
    data = dataProfile.objects.get(xmlData=temp_result["_id"])
  File "/home/mdcs/anaconda2/lib/python2.7/site-packages/django/db/models/manager.py", line 127, in manager_method
    return getattr(self.get_queryset(), name)(*args, **kwargs)
  File "/home/mdcs/anaconda2/lib/python2.7/site-packages/django/db/models/query.py", line 334, in get
    self.model._meta.object_name
DoesNotExist: dataProfile matching query does not exist.
[25/Dec/2017 06:32:09] ERROR [django.request:256] Internal Server Error: /explore/get_results_by_instance_keyword
Traceback (most recent call last):
  File "/home/mdcs/anaconda2/lib/python2.7/site-packages/django/core/handlers/base.py", line 132, in get_response
    response = wrapped_callback(request, *callback_args, **callback_kwargs)
  File "/home/mdcs/Documents/MDCS-stable/explore/ajax.py", line 464, in get_results_by_instance_keyword
    temp1=get_result_list(instanceResults,request)
  File "/home/mdcs/Documents/MDCS-stable/explore/ajax.py", line 527, in get_result_list
    data = dataProfile.objects.get(xmlData=temp_result["_id"])
  File "/home/mdcs/anaconda2/lib/python2.7/site-packages/django/db/models/manager.py", line 127, in manager_method
    return getattr(self.get_queryset(), name)(*args, **kwargs)
  File "/home/mdcs/anaconda2/lib/python2.7/site-packages/django/db/models/query.py", line 334, in get
    self.model._meta.object_name
DoesNotExist: dataProfile matching query does not exist.
[25/Dec/2017 06:32:12] ERROR [django.request:256] Internal Server Error: /explore/get_results_by_instance_keyword
Traceback (most recent call last):
  File "/home/mdcs/anaconda2/lib/python2.7/site-packages/django/core/handlers/base.py", line 132, in get_response
    response = wrapped_callback(request, *callback_args, **callback_kwargs)
  File "/home/mdcs/Documents/MDCS-stable/explore/ajax.py", line 464, in get_results_by_instance_keyword
    temp1=get_result_list(instanceResults,request)
  File "/home/mdcs/Documents/MDCS-stable/explore/ajax.py", line 527, in get_result_list
    data = dataProfile.objects.get(xmlData=temp_result["_id"])
  File "/home/mdcs/anaconda2/lib/python2.7/site-packages/django/db/models/manager.py", line 127, in manager_method
    return getattr(self.get_queryset(), name)(*args, **kwargs)
  File "/home/mdcs/anaconda2/lib/python2.7/site-packages/django/db/models/query.py", line 334, in get
    self.model._meta.object_name
DoesNotExist: dataProfile matching query does not exist.
[25/Dec/2017 07:20:24] ERROR [django.request:256] Internal Server Error: /explore/get_results_by_instance_keyword
Traceback (most recent call last):
  File "/home/mdcs/anaconda2/lib/python2.7/site-packages/django/core/handlers/base.py", line 132, in get_response
    response = wrapped_callback(request, *callback_args, **callback_kwargs)
  File "/home/mdcs/Documents/MDCS-stable/explore/ajax.py", line 464, in get_results_by_instance_keyword
    temp1=get_result_list(instanceResults,request)
  File "/home/mdcs/Documents/MDCS-stable/explore/ajax.py", line 527, in get_result_list
    data = dataProfile.objects.get(xmlData=temp_result["_id"])
  File "/home/mdcs/anaconda2/lib/python2.7/site-packages/django/db/models/manager.py", line 127, in manager_method
    return getattr(self.get_queryset(), name)(*args, **kwargs)
  File "/home/mdcs/anaconda2/lib/python2.7/site-packages/django/db/models/query.py", line 334, in get
    self.model._meta.object_name
DoesNotExist: dataProfile matching query does not exist.
[25/Dec/2017 07:20:36] ERROR [django.request:256] Internal Server Error: /explore/get_results_by_instance_keyword
Traceback (most recent call last):
  File "/home/mdcs/anaconda2/lib/python2.7/site-packages/django/core/handlers/base.py", line 132, in get_response
    response = wrapped_callback(request, *callback_args, **callback_kwargs)
  File "/home/mdcs/Documents/MDCS-stable/explore/ajax.py", line 464, in get_results_by_instance_keyword
    temp1=get_result_list(instanceResults,request)
  File "/home/mdcs/Documents/MDCS-stable/explore/ajax.py", line 527, in get_result_list
    data = dataProfile.objects.get(xmlData=temp_result["_id"])
  File "/home/mdcs/anaconda2/lib/python2.7/site-packages/django/db/models/manager.py", line 127, in manager_method
    return getattr(self.get_queryset(), name)(*args, **kwargs)
  File "/home/mdcs/anaconda2/lib/python2.7/site-packages/django/db/models/query.py", line 334, in get
    self.model._meta.object_name
DoesNotExist: dataProfile matching query does not exist.
[25/Dec/2017 07:20:39] ERROR [django.request:256] Internal Server Error: /explore/get_results_by_instance_keyword
Traceback (most recent call last):
  File "/home/mdcs/anaconda2/lib/python2.7/site-packages/django/core/handlers/base.py", line 132, in get_response
    response = wrapped_callback(request, *callback_args, **callback_kwargs)
  File "/home/mdcs/Documents/MDCS-stable/explore/ajax.py", line 464, in get_results_by_instance_keyword
    temp1=get_result_list(instanceResults,request)
  File "/home/mdcs/Documents/MDCS-stable/explore/ajax.py", line 527, in get_result_list
    data = dataProfile.objects.get(xmlData=temp_result["_id"])
  File "/home/mdcs/anaconda2/lib/python2.7/site-packages/django/db/models/manager.py", line 127, in manager_method
    return getattr(self.get_queryset(), name)(*args, **kwargs)
  File "/home/mdcs/anaconda2/lib/python2.7/site-packages/django/db/models/query.py", line 334, in get
    self.model._meta.object_name
DoesNotExist: dataProfile matching query does not exist.
[25/Dec/2017 07:28:37] ERROR [django.request:256] Internal Server Error: /explore/get_results_by_instance_keyword
Traceback (most recent call last):
  File "/home/mdcs/anaconda2/lib/python2.7/site-packages/django/core/handlers/base.py", line 132, in get_response
    response = wrapped_callback(request, *callback_args, **callback_kwargs)
  File "/home/mdcs/Documents/MDCS-stable/explore/ajax.py", line 464, in get_results_by_instance_keyword
    template = loader.get_template('explore/explore_result_keyword.html')
  File "/home/mdcs/Documents/MDCS-stable/explore/ajax.py", line 527, in get_result_list
    
  File "/home/mdcs/anaconda2/lib/python2.7/site-packages/django/db/models/manager.py", line 127, in manager_method
    return getattr(self.get_queryset(), name)(*args, **kwargs)
  File "/home/mdcs/anaconda2/lib/python2.7/site-packages/django/db/models/query.py", line 334, in get
    self.model._meta.object_name
DoesNotExist: dataProfile matching query does not exist.
