[27/Dec/2017 04:41:17] ERROR [django.request:256] Internal Server Error: /explore/get_results_by_instance_keyword
Traceback (most recent call last):
  File "/home/mdcs/anaconda2/lib/python2.7/site-packages/django/core/handlers/base.py", line 132, in get_response
    response = wrapped_callback(request, *callback_args, **callback_kwargs)
  File "/home/mdcs/Documents/MDCS-stable/explore/ajax.py", line 468, in get_results_by_instance_keyword
    temp1=get_result_list(instanceResults,request)
  File "/home/mdcs/Documents/MDCS-stable/explore/ajax.py", line 538, in get_result_list
    data = dataProfile.objects.get(xmlData=temp_result["_id"])
  File "/home/mdcs/anaconda2/lib/python2.7/site-packages/django/db/models/manager.py", line 127, in manager_method
    return getattr(self.get_queryset(), name)(*args, **kwargs)
  File "/home/mdcs/anaconda2/lib/python2.7/site-packages/django/db/models/query.py", line 334, in get
    self.model._meta.object_name
DoesNotExist: dataProfile matching query does not exist.
[27/Dec/2017 04:53:28] ERROR [django.request:256] Internal Server Error: /explore/get_results_by_instance_keyword
Traceback (most recent call last):
  File "/home/mdcs/anaconda2/lib/python2.7/site-packages/django/core/handlers/base.py", line 132, in get_response
    response = wrapped_callback(request, *callback_args, **callback_kwargs)
  File "/home/mdcs/Documents/MDCS-stable/explore/ajax.py", line 468, in get_results_by_instance_keyword
    temp1=get_result_list(instanceResults,request)
  File "/home/mdcs/Documents/MDCS-stable/explore/ajax.py", line 538, in get_result_list
    data = dataProfile.objects.get(xmlData=temp_result["_id"])
  File "/home/mdcs/anaconda2/lib/python2.7/site-packages/django/db/models/manager.py", line 127, in manager_method
    return getattr(self.get_queryset(), name)(*args, **kwargs)
  File "/home/mdcs/anaconda2/lib/python2.7/site-packages/django/db/models/query.py", line 334, in get
    self.model._meta.object_name
DoesNotExist: dataProfile matching query does not exist.
[27/Dec/2017 04:53:29] ERROR [django.request:256] Internal Server Error: /explore/get_results_by_instance_keyword
Traceback (most recent call last):
  File "/home/mdcs/anaconda2/lib/python2.7/site-packages/django/core/handlers/base.py", line 132, in get_response
    response = wrapped_callback(request, *callback_args, **callback_kwargs)
  File "/home/mdcs/Documents/MDCS-stable/explore/ajax.py", line 468, in get_results_by_instance_keyword
    temp1=get_result_list(instanceResults,request)
  File "/home/mdcs/Documents/MDCS-stable/explore/ajax.py", line 538, in get_result_list
    data = dataProfile.objects.get(xmlData=temp_result["_id"])
  File "/home/mdcs/anaconda2/lib/python2.7/site-packages/django/db/models/manager.py", line 127, in manager_method
    return getattr(self.get_queryset(), name)(*args, **kwargs)
  File "/home/mdcs/anaconda2/lib/python2.7/site-packages/django/db/models/query.py", line 334, in get
    self.model._meta.object_name
DoesNotExist: dataProfile matching query does not exist.
[27/Dec/2017 04:54:01] ERROR [django.request:256] Internal Server Error: /explore/get_results_by_instance_keyword
Traceback (most recent call last):
  File "/home/mdcs/anaconda2/lib/python2.7/site-packages/django/core/handlers/base.py", line 132, in get_response
    response = wrapped_callback(request, *callback_args, **callback_kwargs)
  File "/home/mdcs/Documents/MDCS-stable/explore/ajax.py", line 468, in get_results_by_instance_keyword
    temp1=get_result_list(instanceResults,request)
  File "/home/mdcs/Documents/MDCS-stable/explore/ajax.py", line 538, in get_result_list
    data = dataProfile.objects.get(xmlData=temp_result["_id"])
  File "/home/mdcs/anaconda2/lib/python2.7/site-packages/django/db/models/manager.py", line 127, in manager_method
    return getattr(self.get_queryset(), name)(*args, **kwargs)
  File "/home/mdcs/anaconda2/lib/python2.7/site-packages/django/db/models/query.py", line 334, in get
    self.model._meta.object_name
DoesNotExist: dataProfile matching query does not exist.
[27/Dec/2017 04:54:03] ERROR [django.request:256] Internal Server Error: /explore/get_results_by_instance_keyword
Traceback (most recent call last):
  File "/home/mdcs/anaconda2/lib/python2.7/site-packages/django/core/handlers/base.py", line 132, in get_response
    response = wrapped_callback(request, *callback_args, **callback_kwargs)
  File "/home/mdcs/Documents/MDCS-stable/explore/ajax.py", line 468, in get_results_by_instance_keyword
    temp1=get_result_list(instanceResults,request)
  File "/home/mdcs/Documents/MDCS-stable/explore/ajax.py", line 538, in get_result_list
    data = dataProfile.objects.get(xmlData=temp_result["_id"])
  File "/home/mdcs/anaconda2/lib/python2.7/site-packages/django/db/models/manager.py", line 127, in manager_method
    return getattr(self.get_queryset(), name)(*args, **kwargs)
  File "/home/mdcs/anaconda2/lib/python2.7/site-packages/django/db/models/query.py", line 334, in get
    self.model._meta.object_name
DoesNotExist: dataProfile matching query does not exist.
[27/Dec/2017 05:14:13] WARNING [django.request:170] Not Found: /newpermission/deleteGroup
[27/Dec/2017 05:14:13] WARNING [django.request:170] Not Found: /newpermission/addUsertoGroup
[27/Dec/2017 05:14:13] WARNING [django.request:170] Not Found: /newpermission/creategroup
[27/Dec/2017 05:16:42] WARNING [django.request:98] Forbidden (CSRF token missing or incorrect.): /curate/set_current_template
[27/Dec/2017 22:20:00] ERROR [django.request:256] Internal Server Error: /explore/get_results_by_instance_keyword
Traceback (most recent call last):
  File "/home/mdcs/anaconda2/lib/python2.7/site-packages/django/core/handlers/base.py", line 132, in get_response
    response = wrapped_callback(request, *callback_args, **callback_kwargs)
  File "/home/mdcs/Documents/MDCS-stable/explore/ajax.py", line 468, in get_results_by_instance_keyword
    temp1=get_result_list(instanceResults,request)
  File "/home/mdcs/Documents/MDCS-stable/explore/ajax.py", line 538, in get_result_list
    data = dataProfile.objects.get(xmlData=temp_result["_id"])
  File "/home/mdcs/anaconda2/lib/python2.7/site-packages/django/db/models/manager.py", line 127, in manager_method
    return getattr(self.get_queryset(), name)(*args, **kwargs)
  File "/home/mdcs/anaconda2/lib/python2.7/site-packages/django/db/models/query.py", line 334, in get
    self.model._meta.object_name
DoesNotExist: dataProfile matching query does not exist.
[27/Dec/2017 22:20:14] ERROR [django.request:256] Internal Server Error: /explore/get_results_by_instance_keyword
Traceback (most recent call last):
  File "/home/mdcs/anaconda2/lib/python2.7/site-packages/django/core/handlers/base.py", line 132, in get_response
    response = wrapped_callback(request, *callback_args, **callback_kwargs)
  File "/home/mdcs/Documents/MDCS-stable/explore/ajax.py", line 468, in get_results_by_instance_keyword
    temp1=get_result_list(instanceResults,request)
  File "/home/mdcs/Documents/MDCS-stable/explore/ajax.py", line 538, in get_result_list
    data = dataProfile.objects.get(xmlData=temp_result["_id"])
  File "/home/mdcs/anaconda2/lib/python2.7/site-packages/django/db/models/manager.py", line 127, in manager_method
    return getattr(self.get_queryset(), name)(*args, **kwargs)
  File "/home/mdcs/anaconda2/lib/python2.7/site-packages/django/db/models/query.py", line 334, in get
    self.model._meta.object_name
DoesNotExist: dataProfile matching query does not exist.
[28/Dec/2017 00:35:47] WARNING [django.request:170] Not Found: /favicon.ico
[28/Dec/2017 00:36:53] ERROR [django.request:256] Internal Server Error: /explore/get_results_by_instance_keyword
Traceback (most recent call last):
  File "/home/mdcs/anaconda2/lib/python2.7/site-packages/django/core/handlers/base.py", line 132, in get_response
    response = wrapped_callback(request, *callback_args, **callback_kwargs)
  File "/home/mdcs/Documents/MDCS-stable/explore/ajax.py", line 468, in get_results_by_instance_keyword
    temp1=get_result_list(instanceResults,request)
  File "/home/mdcs/Documents/MDCS-stable/explore/ajax.py", line 538, in get_result_list
    data = dataProfile.objects.get(xmlData=temp_result["_id"])
  File "/home/mdcs/anaconda2/lib/python2.7/site-packages/django/db/models/manager.py", line 127, in manager_method
    return getattr(self.get_queryset(), name)(*args, **kwargs)
  File "/home/mdcs/anaconda2/lib/python2.7/site-packages/django/db/models/query.py", line 334, in get
    self.model._meta.object_name
DoesNotExist: dataProfile matching query does not exist.
[28/Dec/2017 00:37:58] ERROR [django.request:256] Internal Server Error: /explore/get_results_by_instance_keyword
Traceback (most recent call last):
  File "/home/mdcs/anaconda2/lib/python2.7/site-packages/django/core/handlers/base.py", line 132, in get_response
    response = wrapped_callback(request, *callback_args, **callback_kwargs)
  File "/home/mdcs/Documents/MDCS-stable/explore/ajax.py", line 468, in get_results_by_instance_keyword
    temp1=get_result_list(instanceResults,request)
  File "/home/mdcs/Documents/MDCS-stable/explore/ajax.py", line 538, in get_result_list
    data = dataProfile.objects.get(xmlData=temp_result["_id"])
  File "/home/mdcs/anaconda2/lib/python2.7/site-packages/django/db/models/manager.py", line 127, in manager_method
    return getattr(self.get_queryset(), name)(*args, **kwargs)
  File "/home/mdcs/anaconda2/lib/python2.7/site-packages/django/db/models/query.py", line 334, in get
    self.model._meta.object_name
DoesNotExist: dataProfile matching query does not exist.
[28/Dec/2017 01:26:59] DEBUG [oauthlib.oauth2.rfc6749.endpoints.resource:74] Dispatching token_type Bearer request to <oauthlib.oauth2.rfc6749.tokens.BearerToken object at 0x7f2d500e4050>.
[28/Dec/2017 01:29:37] DEBUG [oauthlib.oauth2.rfc6749.endpoints.resource:74] Dispatching token_type Bearer request to <oauthlib.oauth2.rfc6749.tokens.BearerToken object at 0x7f2d500e4ad0>.
[28/Dec/2017 01:32:18] DEBUG [oauthlib.oauth2.rfc6749.endpoints.resource:74] Dispatching token_type Bearer request to <oauthlib.oauth2.rfc6749.tokens.BearerToken object at 0x7f2d500e46b0>.
[28/Dec/2017 01:33:07] DEBUG [oauthlib.oauth2.rfc6749.endpoints.resource:74] Dispatching token_type Bearer request to <oauthlib.oauth2.rfc6749.tokens.BearerToken object at 0x7f85b43fa830>.
[28/Dec/2017 01:47:51] DEBUG [oauthlib.oauth2.rfc6749.endpoints.resource:74] Dispatching token_type Bearer request to <oauthlib.oauth2.rfc6749.tokens.BearerToken object at 0x7f85b442a110>.
[28/Dec/2017 01:48:42] DEBUG [oauthlib.oauth2.rfc6749.endpoints.resource:74] Dispatching token_type Bearer request to <oauthlib.oauth2.rfc6749.tokens.BearerToken object at 0x7f85b442a350>.
[28/Dec/2017 01:49:02] DEBUG [oauthlib.oauth2.rfc6749.endpoints.resource:74] Dispatching token_type Bearer request to <oauthlib.oauth2.rfc6749.tokens.BearerToken object at 0x7f85b442ae30>.
[28/Dec/2017 01:50:32] DEBUG [oauthlib.oauth2.rfc6749.endpoints.resource:74] Dispatching token_type Bearer request to <oauthlib.oauth2.rfc6749.tokens.BearerToken object at 0x7f85b442a590>.
[28/Dec/2017 01:55:33] WARNING [django.request:170] Not Found: /ADMIN
[28/Dec/2017 02:01:22] DEBUG [oauthlib.oauth2.rfc6749.endpoints.resource:74] Dispatching token_type Bearer request to <oauthlib.oauth2.rfc6749.tokens.BearerToken object at 0x7f85b421a6b0>.
[28/Dec/2017 02:01:24] DEBUG [oauthlib.oauth2.rfc6749.endpoints.resource:74] Dispatching token_type Bearer request to <oauthlib.oauth2.rfc6749.tokens.BearerToken object at 0x7f85b435a7d0>.
[06/Mar/2018 01:05:00] WARNING [django.request:170] Not Found: /favicon.ico
[06/Mar/2018 01:05:00] WARNING [django.request:170] Not Found: /favicon.ico
[06/Mar/2018 01:15:03] DEBUG [oauthlib.oauth2.rfc6749.endpoints.resource:74] Dispatching token_type Bearer request to <oauthlib.oauth2.rfc6749.tokens.BearerToken object at 0x7f01149c7590>.
[06/Mar/2018 01:33:24] DEBUG [oauthlib.oauth2.rfc6749.endpoints.resource:74] Dispatching token_type Bearer request to <oauthlib.oauth2.rfc6749.tokens.BearerToken object at 0x7f1b14fbf830>.
[06/Mar/2018 01:36:25] DEBUG [oauthlib.oauth2.rfc6749.endpoints.resource:74] Dispatching token_type Bearer request to <oauthlib.oauth2.rfc6749.tokens.BearerToken object at 0x7f1b14f43590>.
[06/Mar/2018 02:12:16] DEBUG [oauthlib.oauth2.rfc6749.endpoints.resource:74] Dispatching token_type Bearer request to <oauthlib.oauth2.rfc6749.tokens.BearerToken object at 0x7f1b14e95770>.
